Workbook
Name PRINT_AREA_MI: #REF!
Name PRINT_AREA_MI: #REF!
Name PRINT_AREA_MI: #REF!
Name PRINT_AREA_MI: #REF!
Name PRINT_AREA_MI: #REF!
Name PRINT_AREA_MI: #REF!
Name PRINT_AREA_MI: #REF!
Name PRINT_AREA_MI: #REF!
Name PRINT_AREA_MI: #REF!
Name ㅁ1: #REF!
Name ㅁ1: #REF!
Name ㅁ1: #REF!
Name ㅁ1: #REF!
Name ㅁ1: #REF!
Name ㅁ1: #REF!
Name ㅁ1: #REF!
Name ㅁ1: #REF!
Name ㅁ1: #REF!
Name 영재학교: #REF!
Name 초등학교: #REF!
Name 초등학교: #REF!
Name 초등학교: #REF!
Name 초등학교: #REF!
Name 초등학교: #REF!
Name 초등학교: #REF!

Sheet 총괄
A1: □ 2026. 4. 1.자 학교 현황
A2: ▶ 작성기준일: 2026. 4. 1.자
A3: 구분 | C3: 유치원 | F3: 초등학교 | H3: 중학교 | I3: 고등학교 | J3: 특수학교 | K3: 각종학교 | M3: 국제학교 | N3: 방송통신 중고등학교 | O3: 학력인정 평생교육시설 | P3: 합계
C4: 단설 | D4: 병설 | E4: 계 | G4: (분교) | L4: (위탁) | Q4: (분교) | R4: (위탁)
A5: 국립 | B5: 학교수 | F5: =초등학교!D316 -> 1 | I5: =[1]고등학교!$D$212 -> 1 | P5: =E5+F5+H5+I5+J5+N5+K5+M5+O5 -> 2 | Q5: =G5 -> 0 | R5: =L5 -> 0
B6: 학급수 | F6: =초등학교!U316 -> 25 | I6: =고등학교!S212 -> 18 | P6: =E6+F6+H6+I6+J6+N6+K6+M6+O6 -> 43 | Q6: =G6 -> 0 | R6: =L6 -> 0
B7: 학생수 | F7: =초등학교!AH316 -> 543 | I7: =고등학교!Z212 -> 310 | P7: =E7+F7+H7+I7+J7+N7+K7+M7+O7 -> 853 | Q7: =G7 -> 0 | R7: =L7 -> 0
A8: 공립 | B8: 학교수 | C8: 20 | D8: =유치원!E438-C8 -> 183 | E8: =SUM(C8:D8) -> 203 | F8: 263 | G8: 7 | H8: =중학교!D188 -> 137 | I8: =[1]고등학교!$D$213 -> 95 | J8: 6 | K8: 2 | L8: 2 | N8: =방송통신중고등학교!D9 -> 3 | P8: =E8+F8+H8+I8+J8+N8+K8+M8+O8 -> 709 | Q8: =G8 -> 7 | R8: =L8 -> 2
B9: 학급수 | C9: =유치원!BB79+유치원!BB84+유치원!BB85+유치원!BB125+유치원!BB167+유치원!BB204+유치원!BB223+유치원!BB226+유치원!BB275+유치원!BB281+유치원!BB284+유치원!BB329+유치원!BB334+유치원!BB346+유치원!BB348+유치원!BB356+유치원!BB360+유치원!BB361+유치원!BB362+유치원!BB418+유치원!BG79+유치원!BG84+유치원!BG85+유치원!BG125+유치원!BG167+유치원!BG204+유치원!BG223+유치원!BG226+유치원!BG275+유치원!BG281+유치원!BG284+유치원!BG329+유치원!BG334+유치원!BG346+유치원!BG348+유치원!BG356+유치원!BG360+유치원!BG361+유치원!BG362+유치원!BG418 -> 269 | D9: =유치원!BB438+유치원!BG438-C9 -> 479 | E9: =SUM(C9:D9) -> 748 | F9: =초등학교!U317-G9 -> 6789 | G9: =초등학교!U48+초등학교!U49+초등학교!U50+초등학교!U51+초등학교!U52+초등학교!U65+초등학교!U125 -> 18 | H9: =중학교!S188 -> 3048 | I9: =고등학교!S213 -> 2357 | J9: =특수학교!L99 -> 283 | K9: ='각종학교(각종,대안,외국인)'!S8+'각종학교(각종,대안,외국인)'!S9 -> 16 | L9: ='각종학교(각종,대안,외국인)'!S6+'각종학교(각종,대안,외국인)'!S7 -> 15 | N9: =방송통신중고등학교!P9 -> 24 | P9: =E9+F9+H9+I9+J9+N9+K9+M9+O9 -> 13265 | Q9: =G9 -> 18 | R9: =L9 -> 15
B10: 학생수 | C10: =유치원!BF79+유치원!BF84+유치원!BF85+유치원!BF125+유치원!BF167+유치원!BF204+유치원!BF223+유치원!BF226+유치원!BF275+유치원!BF281+유치원!BF284+유치원!BF329+유치원!BF334+유치원!BF346+유치원!BF348+유치원!BF356+유치원!BF360+유치원!BF361+유치원!BF362+유치원!BF418+유치원!BK79+유치원!BK84+유치원!BK85+유치원!BK125+유치원!BK167+유치원!BK204+유치원!BK223+유치원!BK226+유치원!BK275+유치원!BK281+유치원!BK284+유치원!BK329+유치원!BK334+유치원!BK346+유치원!BK348+유치원!BK356+유치원!BK360+유치원!BK361+유치원!BK362+유치원!BK418 -> 3180 | D10: =유치원!BF438+유치원!BK438-C10 -> 4750 | E10: =SUM(C10:D10) -> 7930 | F10: =초등학교!AH317-G10 -> 136131 | G10: =초등학교!AH48+초등학교!AH49+초등학교!AH50+초등학교!AH51+초등학교!AH52+초등학교!AH65+초등학교!AH125 -> 63 | H10: =중학교!Z188 -> 77831 | I10: =고등학교!Z213 -> 55042 | J10: =특수학교!L100 -> 1650 | K10: ='각종학교(각종,대안,외국인)'!AH8+'각종학교(각종,대안,외국인)'!AH9 -> 120 | L10: ='각종학교(각종,대안,외국인)'!AI6+'각종학교(각종,대안,외국인)'!AI7+'각종학교(각종,대안,외국인)'!AI8 -> 1791 | N10: =방송통신중고등학교!W9 -> 531 | P10: =E10+F10+H10+I10+J10+N10+K10+M10+O10 -> 279235 | Q10: =G10 -> 63 | R10: =L10 -> 1791
A11: 사립 | B11: 학교수 | C11: =유치원!E439 -> 188 | E11: =SUM(C11:D11) -> 188 | F11: =초등학교!D318 -> 5 | H11: =중학교!D189 -> 10 | I11: =[1]고등학교!$D$214 -> 33 | J11: 4 | K11: ='각종학교(각종,대안,외국인)'!E14 -> 3 | M11: ='외국교육기관(국제학교)'!D8 -> 2 | O11: =학력인정평생교육시설!D9 -> 2 | P11: =E11+F11+H11+I11+J11+N11+K11+M11+O11 -> 247 | Q11: =G11 -> 0 | R11: =L11 -> 0
B12: 학급수 | C12: =유치원!BB439+유치원!BG439 -> 1212 | E12: =SUM(C12:D12) -> 1212 | F12: =초등학교!U318 -> 79 | H12: =중학교!S189 -> 148 | I12: =고등학교!S214 -> 837 | J12: =특수학교!Q99 -> 81 | K12: ='각종학교(각종,대안,외국인)'!S11+'각종학교(각종,대안,외국인)'!S12+'각종학교(각종,대안,외국인)'!S13 -> 56 | M12: ='외국교육기관(국제학교)'!P8 -> 97 | O12: =학력인정평생교육시설!P9+학력인정평생교육시설!Q9 -> 45 | P12: =E12+F12+H12+I12+J12+N12+K12+M12+O12 -> 2555 | Q12: =G12 -> 0 | R12: =L12 -> 0
B13: 학생수 | C13: =유치원!BF439+유치원!BK439 -> 25257 | E13: =SUM(C13:D13) -> 25257 | F13: =초등학교!AH318 -> 2099 | H13: =중학교!Z189 -> 3667 | I13: =고등학교!Z214 -> 19877 | J13: =특수학교!Q100 -> 377 | K13: ='각종학교(각종,대안,외국인)'!AH11+'각종학교(각종,대안,외국인)'!AH12+'각종학교(각종,대안,외국인)'!AH13 -> 940 | M13: ='외국교육기관(국제학교)'!Y8 -> 1960 | O13: =학력인정평생교육시설!Z9+학력인정평생교육시설!AA9 -> 1297 | P13: =E13+F13+H13+I13+J13+N13+K13+M13+O13 -> 55474 | Q13: =G13 -> 0 | R13: =L13 -> 0
A14: 합계 | B14: 학교수 | C14: =C5+C8+C11 -> 208 | D14: =D5+D8+D11 -> 183 | E14: =E5+E8+E11 -> 391 | F14: =F5+F8+F11 -> 269 | G14: =G5+G8+G11 -> 7 | H14: =H5+H8+H11 -> 147 | I14: =I5+I8+I11 -> 129 | J14: =J5+J8+J11 -> 10 | ... O14: =O5+O8+O11 -> 2 | P14: =E14+F14+H14+I14+J14+N14+K14+M14+O14 -> 958 | Q14: =G14 -> 7 | R14: =L14 -> 2
B15: 학급수 | C15: =C6+C9+C12 -> 1481 | D15: =D6+D9+D12 -> 479 | E15: =E6+E9+E12 -> 1960 | F15: =F6+F9+F12 -> 6893 | G15: =G6+G9+G12 -> 18 | H15: =H6+H9+H12 -> 3196 | I15: =I6+I9+I12 -> 3212 | J15: =J6+J9+J12 -> 364 | ... O15: =O6+O9+O12 -> 45 | P15: =E15+F15+H15+I15+J15+N15+K15+M15+O15 -> 15863 | Q15: =G15 -> 18 | R15: =L15 -> 15
B16: 학생수 | C16: =C7+C10+C13 -> 28437 | D16: =D7+D10+D13 -> 4750 | E16: =E7+E10+E13 -> 33187 | F16: =F7+F10+F13 -> 138773 | G16: =G7+G10+G13 -> 63 | H16: =H7+H10+H13 -> 81498 | I16: =I7+I10+I13 -> 75229 | J16: =J7+J10+J13 -> 2027 | ... O16: =O7+O10+O13 -> 1297 | P16: =E16+F16+H16+I16+J16+N16+K16+M16+O16 -> 335562 | Q16: =G16 -> 63 | R16: =L16 -> 1791
A19: ※ 2025. 4. 1.자와 비교(변동사항)
A20: 구분 | C20: 유치원 | E20: 초등학교 | G20: 중학교 | H20: 고등학교 | I20: 특수학교 | J20: 각종학교 | K20: 국제학교 | L20: 방송통신 중고등학교 | M20: 학력인정 평생교육시설 | N20: 합계 | O20: 비고
C21: 단설 | D21: 병설 | E21: 본교 | F21: 분교
A22: 2025년도 | C22: 211 | D22: 180 | E22: 265 | F22: 7 | G22: 145 | H22: 128 | I22: 10 | J22: 7 | K22: 2 | L22: 3 | M22: 2 | N22: 960
A23: 2026년도 | C23: =C14 -> 208 | D23: =D14 -> 183 | E23: =F14 -> 269 | F23: =G14 -> 7 | G23: =H14 -> 147 | H23: =I14 -> 129 | I23: =J14 -> 10 | J23: =K14+L14 -> 7 | K23: =L14 -> 2 | L23: =N14 -> 3 | M23: =O14 -> 2 | N23: =SUM(C23:M23) -> 967
A24: 증감 | C24: =C23-C22 -> -3 | D24: =D23-D22 -> 3 | E24: =E23-E22 -> 4 | F24: =F23-F22 -> 0 | G24: =G23-G22 -> 2 | H24: =H23-H22 -> 1 | I24: =I23-I22 -> 0 | J24: =J23-J22 -> 0 | ... N24: =N23-N22 -> 7
A25: 개교(원) | B25: 공립 | D25: 3 | E25: 4 | G25: 2 | H25: 1 | N25: =SUM(C25:M25) -> 10 | O25: - 유치원 인천달빛초등학교병설유치원(26.3.) 인천윤슬초등학교병설유치원(26.3.) 인천검단호수초등학교병설유치원(26.3.) - 초등학교 인천신검단초등학교(25.9.) 인천달빛초등학교(26.3.) 인천윤슬초등학교(26.3.) 인천검단호수초등학교(26.3.) - 중학교 인천검단가온중학교(26.3.) 인천단봉중학교(26.3.) - 고등학교 인천운남고등학교(26.3.)
B26: 사립 | N26: =SUM(C26:M26) -> 0
A27: 소계 | C27: =SUM(C25:C26) -> 0 | D27: =SUM(D25:D26) -> 3 | E27: =SUM(E25:E26) -> 4 | F27: =SUM(F25:F26) -> 0 | G27: =SUM(G25:G26) -> 2 | H27: =SUM(H25:H26) -> 1 | I27: =SUM(I25:I26) -> 0 | J27: =SUM(J25:J26) -> 0 | ... N27: =SUM(N25:N26) -> 10
A28: 폐교(원) | B28: 공립 | N28: =SUM(C28:M28) -> 0
B29: 사립 | C29: 3 | N29: =SUM(C29:M29) -> 3 | O29: - 유치원 이노필유치원(25.5.) 뿌리유치원(26.3.) 성아유치원(26.4.)
A30: 소계 | C30: =SUM(C28:C29) -> 3 | D30: =SUM(D28:D29) -> 0 | E30: =SUM(E28:E29) -> 0 | F30: =SUM(F28:F29) -> 0 | G30: =SUM(G28:G29) -> 0 | H30: =SUM(H28:H29) -> 0 | I30: =SUM(I28:I29) -> 0 | J30: =SUM(J28:J29) -> 0 | ... N30: =SUM(N28:N29) -> 3
A31: 합계 | C31: =C27-C30 -> -3 | D31: =D27-D30 -> 3 | E31: =E27-E30 -> 4 | F31: =F27-F30 -> 0 | G31: =G27-G30 -> 2 | H31: =H27-H30 -> 1 | I31: =I27-I30 -> 0 | J31: =J27-J30 -> 0 | ... N31: =N27-N30 -> 7

Sheet 구·군별
A1: □ 구·군별 각급학교 현황
A2: ▶ 작성기준일: 2026. 4. 1.자
A3: 구분 | B3: 유치원 | E3: 초등학교 | K3: 중학교 | N3: 고등학교 | Q3: 특수학교 | T3: 각종학교 | X3: 국제학교 | AA3: 방송통신중고등학교 | AD3: 학력인정평생교육시설 | AG3: 합계
B4: 학교수 | C4: 학급수 | D4: 학생수 | E4: 학교수 | G4: 학급수 | I4: 학생수 | K4: 학교수 | L4: 학급수 | M4: 학생수 | N4: 학교수 | O4: 학급수 | P4: 학생수 | Q4: 학교수 | R4: 학급수 | S4: 학생수 | T4: 학교수 | U4: 학급수 | V4: 학생수 | X4: 학교수 | Y4: 학급수 | Z4: 학생수 | AA4: 학교수 | AB4: 학급수 | AC4: 학생수 | AD4: 학교수 | AE4: 학급수 | AF4: 학생수 | AG4: 학교수 | AI4: 학급수 | AK4: 학생수
F5: 분교 | H5: 분교 | J5: 분교 | W5: (위탁학생수) | AH5: 분교 | AI5: 학급수 | AJ5: 분교 | AL5: 분교 | AM5: (위탁학생수)
A6: 미추홀구 | B6: =유치원!F50 -> 40 | C6: =유치원!BB50+유치원!BG50 -> 173 | D6: =유치원!BF50+유치원!BK50 -> 3057 | E6: =초등학교!E30 -> 23 | G6: =초등학교!U30 -> 717 | I6: =초등학교!AH30 -> 14748 | K6: =중학교!F20 -> 12 | L6: =중학교!S20 -> 303 | M6: =중학교!Z20 -> 7668 | N6: =고등학교!F28 -> 15 | O6: =고등학교!S28 -> 414 | P6: =고등학교!Z28 -> 8104 | Q6: 1 | R6: =특수학교!J99 -> 57 | S6: =특수학교!J100 -> 333 | AD6: 1 | AE6: =학력인정평생교육시설!P7+학력인정평생교육시설!Q7 -> 24 | AF6: =학력인정평생교육시설!Z7+학력인정평생교육시설!AA7 -> 959 | AG6: =B6+E6+K6+N6+Q6+T6+X6+AA6+AD6 -> 92 | AH6: =F6 -> 0 | AI6: =C6+G6+L6+O6+R6+U6+Y6+AB6+AE6 -> 1688 | AJ6: =H6 -> 0 | AK6: =D6+I6+M6+P6+S6+V6+Z6+AC6+AF6 -> 34869 | AL6: =J6 -> 0 | AM6: =W6 -> 0
A7: 동구 | B7: =유치원!F65 -> 12 | C7: =유치원!BB65+유치원!BG65 -> 38 | D7: =유치원!BF65+유치원!BK65 -> 528 | E7: =초등학교!E41 -> 8 | G7: =초등학교!U41 -> 146 | I7: =초등학교!AH41 -> 2803 | K7: =중학교!F26 -> 3 | L7: =중학교!S26 -> 54 | M7: =중학교!Z26 -> 1181 | N7: =고등학교!F35 -> 3 | O7: =고등학교!S35 -> 76 | P7: =고등학교!Z35 -> 1469 | T7: 1 | U7: ='각종학교(각종,대안,외국인)'!S6 -> 9 | W7: ='각종학교(각종,대안,외국인)'!AI6 -> 126 | AG7: =B7+E7+K7+N7+Q7+T7+X7+AA7+AD7 -> 27 | AH7: =F7 -> 0 | AI7: =C7+G7+L7+O7+R7+U7+Y7+AB7+AE7 -> 323 | AJ7: =H7 -> 0 | AK7: =D7+I7+M7+P7+S7+V7+Z7+AC7+AF7 -> 5981 | AL7: =J7 -> 0 | AM7: =W7 -> 126
A8: 중구 | B8: =유치원!F102 -> 21 | C8: =유치원!BB102+유치원!BG102 -> 136 | D8: =유치원!BF102+유치원!BK102 -> 2170 | E8: =(COUNTA(초등학교!E55:E73))-F8 -> 17 | F8: =COUNTA(초등학교!E65) -> 1 | G8: =초등학교!U75-H8 -> 472 | H8: 7 | I8: =초등학교!AH75-J8 -> 9664 | J8: 42 | K8: =중학교!F47 -> 11 | L8: =중학교!S47 -> 231 | M8: =중학교!Z47 -> 5819 | N8: =고등학교!F70 -> 16 | O8: 360 | P8: =고등학교!Z70 -> 7925 | T8: 1 | U8: ='각종학교(각종,대안,외국인)'!S12 -> 13 | V8: ='각종학교(각종,대안,외국인)'!AH12 -> 347 | AA8: 1 | AB8: =방송통신중고등학교!P8 -> 6 | AC8: =방송통신중고등학교!W8 -> 138 | AG8: =B8+E8+K8+N8+Q8+T8+X8+AA8+AD8 -> 67 | AH8: =F8 -> 1 | AI8: =C8+G8+L8+O8+R8+U8+Y8+AB8+AE8 -> 1218 | AJ8: =H8 -> 7 | AK8: =D8+I8+M8+P8+S8+V8+Z8+AC8+AF8 -> 26063 | AL8: =J8 -> 42 | AM8: =W8 -> 0
A9: 옹진군 | B9: =유치원!F78 -> 10 | C9: =유치원!BB78+유치원!BG78 -> 10 | D9: =유치원!BF78+유치원!BK78 -> 38 | E9: =(COUNTA(초등학교!E42:E52))-F9 -> 6 | F9: =COUNTA(초등학교!E48:E52) -> 5 | G9: =초등학교!U54-H9 -> 40 | H9: =초등학교!U48+초등학교!U49+초등학교!U50+초등학교!U51+초등학교!U52 -> 7 | I9: =초등학교!AH54-J9 -> 281 | J9: =초등학교!AH48+초등학교!AH49+초등학교!AH50+초등학교!AH51+초등학교!AH52 -> 15 | K9: =중학교!F33 -> 5 | L9: =중학교!S33 -> 23 | M9: =중학교!Z33 -> 199 | N9: =고등학교!F43 -> 5 | O9: =고등학교!S43 -> 24 | P9: =고등학교!Z43 -> 216 | AG9: =B9+E9+K9+N9+Q9+T9+X9+AA9+AD9 -> 26 | AH9: =F9 -> 5 | AI9: =C9+G9+L9+O9+R9+U9+Y9+AB9+AE9 -> 97 | AJ9: =H9 -> 7 | AK9: =D9+I9+M9+P9+S9+V9+Z9+AC9+AF9 -> 734 | AL9: =J9 -> 15 | AM9: =W9 -> 0
A10: 부평구 | B10: =유치원!F165 -> 60 | C10: =유치원!BB165+유치원!BG165 -> 244 | D10: =유치원!BF165+유치원!BK165 -> 3878 | E10: =초등학교!E120 -> 42 | G10: =초등학교!U120 -> 1005 | I10: =초등학교!AH120 -> 19189 | K10: =중학교!F70 -> 21 | L10: =중학교!S70 -> 453 | M10: =중학교!Z70 -> 11120 | N10: =고등학교!F98 -> 19 | O10: =고등학교!S98 -> 442 | P10: =고등학교!Z98 -> 9934 | Q10: 4 | R10: =특수학교!Q99 -> 81 | S10: =특수학교!Q100 -> 377 | T10: 1 | U10: ='각종학교(각종,대안,외국인)'!S7 -> 6 | W10: ='각종학교(각종,대안,외국인)'!AI7 -> 1661 | AD10: 1 | AE10: =학력인정평생교육시설!P8+학력인정평생교육시설!Q8 -> 21 | AF10: =학력인정평생교육시설!Z8+학력인정평생교육시설!AA8 -> 338 | AG10: =B10+E10+K10+N10+Q10+T10+X10+AA10+AD10 -> 148 | AH10: =F10 -> 0 | AI10: =C10+G10+L10+O10+R10+U10+Y10+AB10+AE10 -> 2252 | AJ10: =H10 -> 0 | AK10: =D10+I10+M10+P10+S10+V10+Z10+AC10+AF10 -> 44836 | AL10: =J10 -> 0 | AM10: =W10 -> 1661
A11: 계양구 | B11: =유치원!F201 -> 33 | C11: =유치원!BB201+유치원!BG201 -> 127 | D11: =유치원!BF201+유치원!BK201 -> 2109 | E11: =(COUNTA(초등학교!E121:E148))-F11 -> 26 | F11: 1 | G11: =초등학교!U150-H11 -> 487 | H11: =초등학교!U125 -> 4 | I11: =초등학교!AH150-J11 -> 9171 | J11: =초등학교!AH125 -> 6 | K11: =중학교!F87 -> 15 | L11: =중학교!S87 -> 258 | M11: =중학교!Z87 -> 5838 | N11: =고등학교!F113 -> 11 | O11: =고등학교!S113 -> 256 | P11: =고등학교!Z113 -> 5850 | Q11: 1 | R11: =특수학교!F99 -> 43 | S11: =특수학교!F100 -> 250 | AG11: =B11+E11+K11+N11+Q11+T11+X11+AA11+AD11 -> 86 | AH11: =F11 -> 1 | AI11: =C11+G11+L11+O11+R11+U11+Y11+AB11+AE11 -> 1171 | AJ11: =H11 -> 4 | AK11: =D11+I11+M11+P11+S11+V11+Z11+AC11+AF11 -> 23218 | AL11: =J11 -> 6 | AM11: =W11 -> 0
A12: 남동구 | B12: =유치원!F265 -> 61 | C12: =유치원!BB265+유치원!BG265 -> 323 | D12: =유치원!BF265+유치원!BK265 -> 5415 | E12: =초등학교!E191 -> 39 | G12: =초등학교!U191 -> 981 | I12: =초등학교!AH191 -> 19810 | K12: =중학교!F112 -> 22 | L12: =중학교!S112 -> 518 | M12: =중학교!Z112 -> 13679 | N12: =고등학교!F136 -> 16 | O12: =고등학교!S136 -> 469 | P12: =고등학교!Z136 -> 11758 | Q12: 2 | R12: =특수학교!H99+특수학교!I99 -> 82 | S12: =특수학교!H100+특수학교!I100 -> 481 | T12: 2 | U12: ='각종학교(각종,대안,외국인)'!S8+'각종학교(각종,대안,외국인)'!S9 -> 16 | V12: ='각종학교(각종,대안,외국인)'!AH8+'각종학교(각종,대안,외국인)'!AH9 -> 120 | W12: ='각종학교(각종,대안,외국인)'!AI8 -> 4 | AA12: 1 | AB12: =방송통신중고등학교!P6 -> 6 | AC12: =방송통신중고등학교!W6 -> 135 | AG12: =B12+E12+K12+N12+Q12+T12+X12+AA12+AD12 -> 143 | AH12: =F12 -> 0 | AI12: =C12+G12+L12+O12+R12+U12+Y12+AB12+AE12 -> 2395 | AJ12: =H12 -> 0 | AK12: =D12+I12+M12+P12+S12+V12+Z12+AC12+AF12 -> 51398 | AL12: =J12 -> 0 | AM12: =W12 -> 4
A13: 연수구 | B13: =유치원!F318 -> 50 | C13: =유치원!BB318+유치원!BG318 -> 332 | D13: =유치원!BF318+유치원!BK318 -> 6174 | E13: =초등학교!E228 -> 34 | G13: =초등학교!U228 -> 1133 | I13: =초등학교!AH228 -> 24805 | K13: =중학교!F135 -> 20 | L13: =중학교!S135 -> 519 | M13: =중학교!Z135 -> 14395 | N13: =고등학교!F160 -> 16 | O13: =고등학교!S160 -> 475 | P13: =고등학교!Z160 -> 12125 | Q13: 1 | R13: =특수학교!G99 -> 48 | S13: =특수학교!G100 -> 285 | T13: 1 | U13: ='각종학교(각종,대안,외국인)'!S11 -> 3 | V13: ='각종학교(각종,대안,외국인)'!AH11 -> 38 | X13: ='외국교육기관(국제학교)'!D8 -> 2 | Y13: ='외국교육기관(국제학교)'!P8 -> 97 | Z13: ='외국교육기관(국제학교)'!Y8 -> 1960 | AA13: 1 | AB13: =방송통신중고등학교!P7 -> 12 | AC13: =방송통신중고등학교!W7 -> 258 | AG13: =B13+E13+K13+N13+Q13+T13+X13+AA13+AD13 -> 125 | AH13: =F13 -> 0 | AI13: =C13+G13+L13+O13+R13+U13+Y13+AB13+AE13 -> 2619 | AJ13: =H13 -> 0 | AK13: =D13+I13+M13+P13+S13+V13+Z13+AC13+AF13 -> 60040 | AL13: =J13 -> 0 | AM13: =W13 -> 0
A14: 서구 | B14: =유치원!F407 -> 86 | C14: =유치원!BB407+유치원!BG407 -> 541 | D14: =유치원!BF407+유치원!BK407 -> 9528 | E14: =초등학교!E284 -> 54 | G14: =초등학교!U284 -> 1754 | I14: =초등학교!AH284 -> 36614 | K14: =중학교!F166 -> 29 | L14: =중학교!S166 -> 769 | M14: =중학교!Z166 -> 20364 | N14: =고등학교!F188 -> 20 | O14: =고등학교!S188 -> 613 | P14: =고등학교!Z188 -> 16205 | Q14: 1 | R14: =특수학교!K99 -> 53 | S14: =특수학교!K100 -> 301 | T14: 1 | U14: ='각종학교(각종,대안,외국인)'!S13 -> 40 | V14: ='각종학교(각종,대안,외국인)'!AH13 -> 555 | AG14: =B14+E14+K14+N14+Q14+T14+X14+AA14+AD14 -> 191 | AH14: =F14 -> 0 | AI14: =C14+G14+L14+O14+R14+U14+Y14+AB14+AE14 -> 3770 | AJ14: =H14 -> 0 | AK14: =D14+I14+M14+P14+S14+V14+Z14+AC14+AF14 -> 83567 | AL14: =J14 -> 0 | AM14: =W14 -> 0
A15: 강화군 | B15: =유치원!F428 -> 18 | C15: =유치원!BB428+유치원!BG428 -> 36 | D15: =유치원!BF428+유치원!BK428 -> 290 | E15: =초등학교!E306 -> 20 | G15: =초등학교!U306 -> 158 | I15: =초등학교!AH306 -> 1688 | K15: =중학교!F178 -> 9 | L15: =중학교!S178 -> 68 | M15: =중학교!Z178 -> 1235 | N15: =고등학교!F203 -> 8 | O15: =고등학교!S203 -> 83 | P15: =고등학교!Z203 -> 1643 | AG15: =B15+E15+K15+N15+Q15+T15+X15+AA15+AD15 -> 55 | AH15: =F15 -> 0 | AI15: =C15+G15+L15+O15+R15+U15+Y15+AB15+AE15 -> 345 | AJ15: =H15 -> 0 | AK15: =D15+I15+M15+P15+S15+V15+Z15+AC15+AF15 -> 4856 | AL15: =J15 -> 0 | AM15: =W15 -> 0
A16: 합계 | B16: =SUM(B6:B15) -> 391 | C16: =SUM(C6:C15) -> 1960 | D16: =SUM(D6:D15) -> 33187 | E16: =SUM(E6:E15) -> 269 | F16: =SUM(F6:F15) -> 7 | G16: =SUM(G6:G15) -> 6893 | H16: =SUM(H6:H15) -> 18 | I16: =SUM(I6:I15) -> 138773 | ... AM16: =SUM(AM6:AM15) -> 1791
A18: ※ 학급수: 일반학급+특수학급+한국어학급
A22: □ 행정개편 이후 구·군별 각급학교 현황(2026.7.1.시행)
A23: ▶ 작성기준일: 2026. 4. 1.자
A24: 구분 | B24: 유치원 | E24: 초등학교 | K24: 중학교 | N24: 고등학교 | Q24: 특수학교 | T24: 각종학교 | X24: 국제학교 | AA24: 방송통신중고등학교 | AD24: 학력인정평생교육시설 | AG24: 합계
B25: 학교수 | C25: 학급수 | D25: 학생수 | E25: 학교수 | G25: 학급수 | I25: 학생수 | K25: 학교수 | L25: 학급수 | M25: 학생수 | N25: 학교수 | O25: 학급수 | P25: 학생수 | Q25: 학교수 | R25: 학급수 | S25: 학생수 | T25: 학교수 | U25: 학급수 | V25: 학생수 | X25: 학교수 | Y25: 학급수 | Z25: 학생수 | AA25: 학교수 | AB25: 학급수 | AC25: 학생수 | AD25: 학교수 | AE25: 학급수 | AF25: 학생수 | AG25: 학교수 | AI25: 학급수 | AK25: 학생수
F26: 분교 | H26: 분교 | J26: 분교 | W26: (위탁학생수) | AH26: 분교 | AI26: 학급수 | AJ26: 분교 | AL26: 분교 | AM26: (위탁학생수)
A27: 미추홀구 | B27: =유치원!F50 -> 40 | C27: =유치원!BB50+유치원!BG50 -> 173 | D27: =유치원!BF50+유치원!BK50 -> 3057 | E27: =E6 -> 23 | G27: =G6 -> 717 | I27: =I6 -> 14748 | K27: =K6 -> 12 | L27: =L6 -> 303 | M27: =M6 -> 7668 | N27: =N6 -> 15 | O27: =O6 -> 414 | P27: =P6 -> 8104 | Q27: =Q6 -> 1 | R27: =R6 -> 57 | ... AF27: =AF6 -> 959 | AG27: =B27+E27+K27+N27+Q27+T27+X27+AA27+AD27 -> 92 | AH27: =F27 -> 0 | AI27: =C27+G27+L27+O27+R27+U27+Y27+AB27+AE27 -> 1688 | AJ27: =H27 -> 0 | AK27: =D27+I27+M27+P27+S27+V27+Z27+AC27+AF27 -> 34869 | AL27: =J27 -> 0 | AM27: =AM6 -> 0
A28: 제물포구 | B28: 19 | C28: 76 | D28: 900 | E28: 14 | G28: 258 | I28: 4764 | K28: 8 | L28: 135 | M28: 2848 | N28: 11 | O28: 262 | P28: 5065 | T28: 2 | U28: =9+13 -> 22 | V28: 347 | W28: =W7 -> 126 | AA28: 1 | AB28: 6 | AC28: 138 | AG28: =B28+E28+K28+N28+Q28+T28+X28+AA28+AD28 -> 55 | AH28: =F28 -> 0 | AI28: =C28+G28+L28+O28+R28+U28+Y28+AB28+AE28 -> 759 | AJ28: =H28 -> 0 | AK28: =D28+I28+M28+P28+S28+V28+Z28+AC28+AF28 -> 14062 | AL28: =J28 -> 0 | AM28: =W28 -> 126
A29: 영종구 | B29: 14 | C29: =90+8 -> 98 | D29: =1767+31 -> 1798 | E29: 11 | F29: 1 | G29: 360 | H29: =초등학교!U65 -> 7 | I29: 7703 | J29: =초등학교!AH65 -> 42 | K29: 6 | L29: 150 | M29: 4152 | N29: 8 | O29: 174 | P29: 4329 | AG29: =B29+E29+K29+N29+Q29+T29+X29+AA29+AD29 -> 39 | AH29: =F29 -> 1 | AI29: =C29+G29+L29+O29+R29+U29+Y29+AB29+AE29 -> 782 | AJ29: =H29 -> 7 | AK29: =D29+I29+M29+P29+S29+V29+Z29+AC29+AF29 -> 17982 | AL29: =J29 -> 42 | AM29: =W29 -> 0
A30: 옹진군 | B30: =B9 -> 10 | C30: =C9 -> 10 | D30: =D9 -> 38 | E30: =E9 -> 6 | F30: =F9 -> 5 | G30: =G9 -> 40 | H30: =H9 -> 7 | I30: =I9 -> 281 | ... AF30: =AF9 -> 0 | AG30: =B30+E30+K30+N30+Q30+T30+X30+AA30+AD30 -> 26 | AH30: =F30 -> 5 | AI30: =C30+G30+L30+O30+R30+U30+Y30+AB30+AE30 -> 97 | AJ30: =H30 -> 7 | AK30: =D30+I30+M30+P30+S30+V30+Z30+AC30+AF30 -> 734 | AL30: =J30 -> 15 | AM30: =AM9 -> 0
A31: 부평구 | B31: =B10 -> 60 | C31: =C10 -> 244 | D31: =D10 -> 3878 | E31: =E10 -> 42 | F31: =F10 -> 0 | G31: =G10 -> 1005 | H31: =H10 -> 0 | I31: =I10 -> 19189 | ... AF31: =AF10 -> 338 | AG31: =B31+E31+K31+N31+Q31+T31+X31+AA31+AD31 -> 148 | AH31: =F31 -> 0 | AI31: =C31+G31+L31+O31+R31+U31+Y31+AB31+AE31 -> 2252 | AJ31: =H31 -> 0 | AK31: =D31+I31+M31+P31+S31+V31+Z31+AC31+AF31 -> 44836 | AL31: =J31 -> 0 | AM31: 1661
A32: 계양구 | B32: =B11 -> 33 | C32: =C11 -> 127 | D32: =D11 -> 2109 | E32: =E11 -> 26 | F32: =F11 -> 1 | G32: =G11 -> 487 | H32: =H11 -> 4 | I32: =I11 -> 9171 | ... AF32: =AF11 -> 0 | AG32: =B32+E32+K32+N32+Q32+T32+X32+AA32+AD32 -> 86 | AH32: =F32 -> 1 | AI32: =C32+G32+L32+O32+R32+U32+Y32+AB32+AE32 -> 1171 | AJ32: =H32 -> 4 | AK32: =D32+I32+M32+P32+S32+V32+Z32+AC32+AF32 -> 23218 | AL32: =J32 -> 6 | AM32: 0
A33: 남동구 | B33: =B12 -> 61 | C33: =C12 -> 323 | D33: =D12 -> 5415 | E33: =E12 -> 39 | F33: =F12 -> 0 | G33: =G12 -> 981 | H33: =H12 -> 0 | I33: =I12 -> 19810 | ... AF33: =AF12 -> 0 | AG33: =B33+E33+K33+N33+Q33+T33+X33+AA33+AD33 -> 143 | AH33: =F33 -> 0 | AI33: =C33+G33+L33+O33+R33+U33+Y33+AB33+AE33 -> 2395 | AJ33: =H33 -> 0 | AK33: =D33+I33+M33+P33+S33+V33+Z33+AC33+AF33 -> 51398 | AL33: =J33 -> 0 | AM33: 4
A34: 연수구 | B34: =B13 -> 50 | C34: =C13 -> 332 | D34: =D13 -> 6174 | E34: =E13 -> 34 | F34: =F13 -> 0 | G34: =G13 -> 1133 | H34: =H13 -> 0 | I34: =I13 -> 24805 | ... AF34: =AF13 -> 0 | AG34: =B34+E34+K34+N34+Q34+T34+X34+AA34+AD34 -> 125 | AH34: =F34 -> 0 | AI34: =C34+G34+L34+O34+R34+U34+Y34+AB34+AE34 -> 2619 | AJ34: =H34 -> 0 | AK34: =D34+I34+M34+P34+S34+V34+Z34+AC34+AF34 -> 60040 | AL34: =J34 -> 0 | AM34: 0
A35: 서구 | B35: 47 | C35: 269 | D35: =4755+74 -> 4829 | E35: 32 | G35: 933 | I35: 19489 | K35: 19 | L35: 428 | M35: 11500 | N35: 12 | O35: 362 | P35: 9325 | T35: 1 | U35: 40 | V35: 555 | AG35: =B35+E35+K35+N35+Q35+T35+X35+AA35+AD35 -> 111 | AH35: =F35 -> 0 | AI35: =C35+G35+L35+O35+R35+U35+Y35+AB35+AE35 -> 2032 | AJ35: =H35 -> 0 | AK35: =D35+I35+M35+P35+S35+V35+Z35+AC35+AF35 -> 45698 | AL35: =J35 -> 0 | AM35: =W35 -> 0
A36: 검단구 | B36: 39 | C36: 272 | D36: =4619+80 -> 4699 | E36: 22 | G36: 821 | I36: 17125 | K36: 10 | L36: 341 | M36: 8864 | N36: 8 | O36: 251 | P36: 6880 | Q36: 1 | R36: 53 | S36: 301 | AG36: =B36+E36+K36+N36+Q36+T36+X36+AA36+AD36 -> 80 | AH36: =F36 -> 0 | AI36: =C36+G36+L36+O36+R36+U36+Y36+AB36+AE36 -> 1738 | AJ36: =H36 -> 0 | AK36: =D36+I36+M36+P36+S36+V36+Z36+AC36+AF36 -> 37869 | AL36: =J36 -> 0 | AM36: =W36 -> 0
A37: 강화군 | B37: =B15 -> 18 | C37: =C15 -> 36 | D37: =D15 -> 290 | E37: =E15 -> 20 | G37: =G15 -> 158 | I37: =I15 -> 1688 | K37: =K15 -> 9 | L37: =L15 -> 68 | M37: =M15 -> 1235 | N37: =N15 -> 8 | O37: =O15 -> 83 | P37: =P15 -> 1643 | Q37: =Q15 -> 0 | R37: =R15 -> 0 | ... AF37: =AF15 -> 0 | AG37: =B37+E37+K37+N37+Q37+T37+X37+AA37+AD37 -> 55 | AH37: =F37 -> 0 | AI37: =C37+G37+L37+O37+R37+U37+Y37+AB37+AE37 -> 345 | AJ37: =H37 -> 0 | AK37: =D37+I37+M37+P37+S37+V37+Z37+AC37+AF37 -> 4856 | AL37: =J37 -> 0 | AM37: =AM15 -> 0
A38: 합계 | B38: =SUM(B27:B37) -> 391 | C38: =SUM(C27:C37) -> 1960 | D38: =SUM(D27:D37) -> 33187 | E38: =SUM(E27:E37) -> 269 | F38: =SUM(F27:F37) -> 7 | G38: =SUM(G27:G37) -> 6893 | H38: =SUM(H27:H37) -> 18 | I38: =SUM(I27:I37) -> 138773 | ... AM38: =SUM(AM27:AM37) -> 1791
A40: ※ 학급수: 일반학급+특수학급+한국어학급
AK41: =AK16-AK38 -> 0

Sheet (계열별)고등학교
A1: □ 계열별 고등학교 현황
A2: ▶ 작성기준일: 2026. 4. 1.자
A3: 구분 | B3: 일반계고등학교 | E3: 특성화고등학교 | H3: 특수목적고등학교 | K3: 자율형고등학교 | N3: 합계
B4: 학교수 | C4: 학급수 | D4: 학생수 | E4: 학교수 | F4: 학급수 | G4: 학생수 | H4: 학교수 | I4: 학급수 | J4: 학생수 | K4: 학교수 | L4: 학급수 | M4: 학생수 | N4: 학교수 | O4: 학급수 | P4: 학생수
A5: 미추홀구 | B5: =고등학교!D11+고등학교!D24 -> 8 | C5: =고등학교!S11+고등학교!S24 -> 225 | D5: =고등학교!Z11+고등학교!Z24 -> 4879 | E5: =고등학교!D17+고등학교!D26 -> 6 | F5: =고등학교!S17+고등학교!S26 -> 165 | G5: =고등학교!Z17+고등학교!Z26 -> 2876 | H5: =고등학교!D19 -> 1 | I5: =고등학교!S19 -> 24 | J5: =고등학교!Z19 -> 349 | N5: =B5+E5+H5+K5 -> 15 | O5: =C5+F5+I5+L5 -> 414 | P5: =D5+G5+J5+M5 -> 8104
A6: 동구 | B6: =고등학교!D30 -> 1 | C6: =고등학교!S30 -> 22 | D6: =고등학교!Z30 -> 454 | E6: =고등학교!D33 -> 2 | F6: =고등학교!S33 -> 54 | G6: =고등학교!Z33 -> 1015 | N6: =B6+E6+H6+K6 -> 3 | O6: =C6+F6+I6+L6 -> 76 | P6: =D6+G6+J6+M6 -> 1469
A7: 옹진군 | B7: =고등학교!D41 -> 5 | C7: =고등학교!S41 -> 24 | D7: =고등학교!Z41 -> 216 | N7: =B7+E7+H7+K7 -> 5 | O7: =C7+F7+I7+L7 -> 24 | P7: =D7+G7+J7+M7 -> 216
A8: 중구 | B8: =고등학교!D53+고등학교!D64 -> 8 | C8: =고등학교!S53+고등학교!S64 -> 198 | D8: =고등학교!Z53+고등학교!Z64 -> 4863 | E8: =고등학교!D57+고등학교!D66 -> 4 | F8: =고등학교!S57+고등학교!S66 -> 90 | G8: =고등학교!Z57+고등학교!Z66 -> 1471 | H8: =고등학교!D45+고등학교!D60 -> 3 | I8: =고등학교!S45+고등학교!S60 -> 48 | J8: =고등학교!Z45+고등학교!Z60 -> 925 | K8: 1 | L8: 24 | M8: 666 | N8: =B8+E8+H8+K8 -> 16 | O8: =C8+F8+I8+L8 -> 360 | P8: =D8+G8+J8+M8 -> 7925
A9: 부평구 | B9: =고등학교!D82+고등학교!D92 -> 14 | C9: =고등학교!S82+고등학교!S92 -> 327 | D9: =고등학교!Z82+고등학교!Z92 -> 7824 | E9: =고등학교!D85+고등학교!D94 -> 3 | F9: =고등학교!S85+고등학교!S94 -> 76 | G9: =고등학교!Z85+고등학교!Z94 -> 1210 | H9: =고등학교!D87+고등학교!D96 -> 2 | I9: =고등학교!S87+고등학교!S96 -> 39 | J9: =고등학교!Z87+고등학교!Z96 -> 900 | N9: =B9+E9+H9+K9 -> 19 | O9: =C9+F9+I9+L9 -> 442 | P9: =D9+G9+J9+M9 -> 9934
A10: 계양구 | B10: =고등학교!D109 -> 10 | C10: =고등학교!S109 -> 225 | D10: =고등학교!Z109 -> 5418 | E10: =고등학교!D111 -> 1 | F10: =고등학교!S111 -> 31 | G10: =고등학교!Z111 -> 432 | N10: =B10+E10+H10+K10 -> 11 | O10: =C10+F10+I10+L10 -> 256 | P10: =D10+G10+J10+M10 -> 5850
A11: 남동구 | B11: =고등학교!D123+고등학교!D132 -> 13 | C11: =고등학교!S123+고등학교!S132 -> 397 | D11: =고등학교!Z123+고등학교!Z132 -> 10234 | E11: =고등학교!D134 -> 1 | F11: =고등학교!S134 -> 27 | G11: =고등학교!Z134 -> 505 | H11: =고등학교!D126 -> 2 | I11: =고등학교!S126 -> 45 | J11: =고등학교!Z126 -> 1019 | N11: =B11+E11+H11+K11 -> 16 | O11: =C11+F11+I11+L11 -> 469 | P11: =D11+G11+J11+M11 -> 11758
A12: 연수구 | B12: =고등학교!D144+고등학교!D156 -> 10 | C12: =고등학교!S144+고등학교!S156 -> 331 | D12: =고등학교!Z144+고등학교!Z156 -> 9444 | E12: =고등학교!D149 -> 4 | F12: =고등학교!S149 -> 105 | G12: =고등학교!Z149 -> 1720 | H12: =고등학교!D151 -> 1 | I12: =고등학교!S151 -> 15 | J12: =고등학교!Z151 -> 238 | K12: 1 | L12: 24 | M12: 723 | N12: =B12+E12+H12+K12 -> 16 | O12: =C12+F12+I12+L12 -> 475 | P12: =D12+G12+J12+M12 -> 12125
A13: 서구 | B13: =고등학교!D174+고등학교!D182 -> 15 | C13: =고등학교!S174+고등학교!S182 -> 505 | D13: =고등학교!Z174+고등학교!Z182 -> 14091 | E13: =고등학교!D176+고등학교!D186 -> 4 | F13: =고등학교!S176+고등학교!S186 -> 98 | G13: =고등학교!Z176+고등학교!Z186 -> 1831 | H13: =고등학교!D178 -> 1 | I13: =고등학교!S178 -> 10 | J13: =고등학교!Z178 -> 283 | N13: =B13+E13+H13+K13 -> 20 | O13: =C13+F13+I13+L13 -> 613 | P13: =D13+G13+J13+M13 -> 16205
A14: 강화군 | B14: =고등학교!D193+고등학교!D198 -> 5 | C14: =고등학교!S193+고등학교!S198 -> 57 | D14: =고등학교!Z193+고등학교!Z198 -> 1186 | E14: =고등학교!D195+고등학교!D201 -> 3 | F14: =고등학교!S195+고등학교!S201 -> 26 | G14: =고등학교!Z195+고등학교!Z201 -> 457 | N14: =B14+E14+H14+K14 -> 8 | O14: =C14+F14+I14+L14 -> 83 | P14: =D14+G14+J14+M14 -> 1643
A15: 합계 | B15: =SUM(B5:B14) -> 89 | C15: =SUM(C5:C14) -> 2311 | D15: =SUM(D5:D14) -> 58609 | E15: =SUM(E5:E14) -> 28 | F15: =SUM(F5:F14) -> 672 | G15: =SUM(G5:G14) -> 11517 | H15: =SUM(H5:H14) -> 10 | I15: =SUM(I5:I14) -> 181 | ... P15: =SUM(P5:P14) -> 75229
A19: □ 행정개편 이후 계열별 고등학교 현황(2026.7.1.시행)
A20: ▶ 작성기준일: 2026. 4. 1.자
A21: 구분 | B21: 일반계고등학교 | E21: 특성화고등학교 | H21: 특수목적고등학교 | K21: 자율형고등학교 | N21: 합계
B22: 학교수 | C22: 학급수 | D22: 학생수 | E22: 학교수 | F22: 학급수 | G22: 학생수 | H22: 학교수 | I22: 학급수 | J22: 학생수 | K22: 학교수 | L22: 학급수 | M22: 학생수 | N22: 학교수 | O22: 학급수 | P22: 학생수
A23: 미추홀구 | B23: =B5 -> 8 | C23: =C5 -> 225 | D23: =D5 -> 4879 | E23: =E5 -> 6 | F23: =F5 -> 165 | G23: =G5 -> 2876 | H23: =H5 -> 1 | I23: =I5 -> 24 | ... M23: =M5 -> 0 | N23: =B23+E23+H23+K23 -> 15 | O23: =C23+F23+I23+L23 -> 414 | P23: =D23+G23+J23+M23 -> 8104
A24: 제물포구 | B24: 5 | C24: 112 | D24: 2476 | E24: 5 | F24: 132 | G24: 2279 | H24: 1 | I24: 18 | J24: 310 | N24: =B24+E24+H24+K24 -> 11 | O24: =C24+F24+I24+L24 -> 262 | P24: =D24+G24+J24+M24 -> 5065
A25: 영종구 | B25: 4 | C25: 108 | D25: 2841 | E25: 1 | F25: 12 | G25: 207 | H25: 2 | I25: 30 | J25: 615 | K25: 1 | L25: 24 | M25: 666 | N25: =B25+E25+H25+K25 -> 8 | O25: =C25+F25+I25+L25 -> 174 | P25: =D25+G25+J25+M25 -> 4329
A26: 옹진군 | B26: =B7 -> 5 | C26: =C7 -> 24 | D26: =D7 -> 216 | E26: =E7 -> 0 | F26: =F7 -> 0 | G26: =G7 -> 0 | H26: =H7 -> 0 | I26: =I7 -> 0 | ... M26: =M7 -> 0 | N26: =B26+E26+H26+K26 -> 5 | O26: =C26+F26+I26+L26 -> 24 | P26: =D26+G26+J26+M26 -> 216
A27: 부평구 | B27: =B9 -> 14 | C27: =C9 -> 327 | D27: =D9 -> 7824 | E27: =E9 -> 3 | F27: =F9 -> 76 | G27: =G9 -> 1210 | H27: =H9 -> 2 | I27: =I9 -> 39 | ... N27: =N9 -> 19 | O27: =C27+F27+I27+L27 -> 442 | P27: =D27+G27+J27+M27 -> 9934
A28: 계양구 | B28: =B10 -> 10 | C28: =C10 -> 225 | D28: =D10 -> 5418 | E28: =E10 -> 1 | F28: =F10 -> 31 | G28: =G10 -> 432 | H28: =H10 -> 0 | I28: =I10 -> 0 | ... N28: =N10 -> 11 | O28: =C28+F28+I28+L28 -> 256 | P28: =D28+G28+J28+M28 -> 5850
A29: 남동구 | B29: =B11 -> 13 | C29: =C11 -> 397 | D29: =D11 -> 10234 | E29: =E11 -> 1 | F29: =F11 -> 27 | G29: =G11 -> 505 | H29: =H11 -> 2 | I29: =I11 -> 45 | ... N29: =N11 -> 16 | O29: =C29+F29+I29+L29 -> 469 | P29: =D29+G29+J29+M29 -> 11758
A30: 연수구 | B30: =B12 -> 10 | C30: =C12 -> 331 | D30: =D12 -> 9444 | E30: =E12 -> 4 | F30: =F12 -> 105 | G30: =G12 -> 1720 | H30: =H12 -> 1 | I30: =I12 -> 15 | ... N30: =N12 -> 16 | O30: =C30+F30+I30+L30 -> 475 | P30: =D30+G30+J30+M30 -> 12125
A31: 서구 | B31: 9 | C31: 296 | D31: 7999 | E31: 2 | F31: 56 | G31: 1043 | H31: 1 | I31: 10 | J31: 283 | N31: =B31+E31+H31+K31 -> 12 | O31: =C31+F31+I31+L31 -> 362 | P31: =D31+G31+J31+M31 -> 9325
A32: 검단구 | B32: 6 | C32: 209 | D32: 6092 | E32: 2 | F32: 42 | G32: 788 | N32: =B32+E32+H32+K32 -> 8 | O32: =C32+F32+I32+L32 -> 251 | P32: =D32+G32+J32+M32 -> 6880
A33: 강화군 | B33: 5 | C33: 57 | D33: 1186 | E33: 3 | F33: 26 | G33: 457 | N33: =B33+E33+H33+K33 -> 8 | O33: =C33+F33+I33+L33 -> 83 | P33: =D33+G33+J33+M33 -> 1643
A34: 합계 | B34: =SUM(B23:B33) -> 89 | C34: =SUM(C23:C33) -> 2311 | D34: =SUM(D23:D33) -> 58609 | E34: =SUM(E23:E33) -> 28 | F34: =SUM(F23:F33) -> 672 | G34: =SUM(G23:G33) -> 11517 | H34: =SUM(H23:H33) -> 10 | I34: =SUM(I23:I33) -> 181 | ... P34: =SUM(P23:P33) -> 75229

Sheet 유치원
A1: □ 유치원 현황
A2: ▶ 작성기준일: 2026. 4. 1.자
A3: 취원권역 | B3: 구군별 | C3: 개편후 행정구역(2026.7.1.시행) | D3: 행정동 | E3: 설립별 | F3: 유치원명 | G3: 개원일자 | H3: 주소 | I3: 교지면적(㎡) | J3: 우편번호 | K3: 전화번호 | L3: 팩스번호 | M3: 인가 (정원) | P3: 편성 | BL3: 비고
P4: 일반학급 | V4: 특수학급 | AB4: 혼합반 | BB4: 일반학급 계 | BG4: 특수학급 계
P5: 3세반 | R5: 4세반 | T5: 5세반 | V5: 3세반 | X5: 4세반 | Z5: 5세반 | AB5: 3~4세반 | AJ5: 4~5세반 | AR5: 3~5세반 | BB5: 학급수 | BC5: 원아수 | BG5: 학급수 | BH5: 원아수
M6: 일반학급 | N6: 특수학급 | O6: 원아수 | P6: 학급수 | Q6: 원아수 | R6: 학급수 | S6: 원아수 | T6: 학급수 | U6: 원아수 | V6: 학급수 | W6: 원아수 | X6: 학급수 | Y6: 원아수 | Z6: 학급수 | AA6: 원아수 | AB6: 일반학급수 | AC6: 특수학급수 | AD6: 일반학급 원아수 | AG6: 특수학급 원아수 | AJ6: 일반학급수 | AK6: 특수학급수 | AL6: 일반학급 원아수 | AO6: 특수학급 원아수 | AR6: 일반학급수 | AS6: 특수학급수 | AT6: 일반학급 원아수 | AX6: 특수학급 원아수
AD7: 3세 | AE7: 4세 | AF7: 계 | AG7: 3세 | AH7: 4세 | AI7: 계 | AL7: 4세 | AM7: 5세 | AN7: 계 | AO7: 4세 | AP7: 5세 | AQ7: 계 | AT7: 3세 | AU7: 4세 | AV7: 5세 | AW7: 계 | AX7: 3세 | AY7: 4세 | AZ7: 5세 | BA7: 계 | BC7: 3세 | BD7: 4세 | BE7: 5세 | BF7: 계 | BH7: 3세 | BI7: 4세 | BJ7: 5세 | BK7: 계
A8: 3권역 | B8: 미추홀구 | C8: 미추홀구 | D8: 도화동 | E8: 공립 | F8: 인천대화초등학교병설유치원 | G8: 41334 | H8: 미추홀구 석정로 301번길(도화동 105-11) | I8: 11867 | J8: 22116 | K8: 629-1483 | L8: 867-1356 | M8: 2 | N8: 0 | O8: 36 | P8: 0 | Q8: 0 | R8: 0 | S8: 0 | T8: 1 | U8: 4 | V8: 0 | W8: 0 | X8: 0 | Y8: 0 | Z8: 0 | AA8: 0 | AB8: 1 | AC8: 0 | AD8: 1 | AE8: 3 | AF8: =SUM(AD8:AE8) -> 4 | AG8: 0 | AH8: 0 | AI8: =SUM(AG8:AH8) -> 0 | AJ8: 0 | AK8: 0 | AL8: 0 | AM8: 0 | AN8: =SUM(AL8:AM8) -> 0 | AO8: 0 | AP8: 0 | AQ8: 0 | AR8: 0 | AS8: 0 | AT8: 0 | AU8: 0 | AV8: 0 | AW8: 0 | AX8: 0 | AY8: 0 | AZ8: 0 | BA8: 0 | BB8: =SUM(P8,R8,T8,AB8,AJ8,AR8) -> 2 | BC8: =SUM(Q8,AD8,AT8) -> 1 | BD8: =SUM(S8,AE8,AL8,AU8) -> 3 | BE8: =SUM(U8,AM8,AV8) -> 4 | BF8: =SUM(BC8:BE8) -> 8 | BG8: =SUM(V8,X8,Z8,AC8,AK8,AS8) -> 0 | BH8: =SUM(W8,AG8,AX8) -> 0 | BI8: =SUM(Y8,AH8,AO8,AY8) -> 0 | BJ8: =SUM(AA8,AP8,AZ8) -> 0 | BK8: =SUM(BH8:BJ8) -> 0
A9: 3권역 | B9: 미추홀구 | C9: 미추홀구 | D9: 도화동 | E9: 공립 | F9: 인천도화초등학교병설유치원 | G9: 41334 | H9: 미추홀구 경인로 242(도화동 541-5) | I9: 12366 | J9: 22165 | K9: 629-0575 | L9: 865-6137 | M9: 2 | N9: 1 | O9: 36 | T9: 1 | U9: 7 | AB9: 1 | AD9: 6 | AE9: 7 | AF9: =SUM(AD9:AE9) -> 13 | AI9: =SUM(AG9:AH9) -> 0 | AN9: =SUM(AL9:AM9) -> 0 | AQ9: =SUM(AO9:AP9) -> 0 | AS9: 1 | AW9: =SUM(AT9:AV9) -> 0 | AZ9: 1 | BA9: =SUM(AX9:AZ9) -> 1 | BB9: =SUM(P9,R9,T9,AB9,AJ9,AR9) -> 2 | BC9: =SUM(Q9,AD9,AT9) -> 6 | BD9: =SUM(S9,AE9,AL9,AU9) -> 7 | BE9: =SUM(U9,AM9,AV9) -> 7 | BF9: =SUM(BC9:BE9) -> 20 | BG9: =SUM(V9,X9,Z9,AC9,AK9,AS9) -> 1 | BH9: =SUM(W9,AG9,AX9) -> 0 | BI9: =SUM(Y9,AH9,AO9,AY9) -> 0 | BJ9: =SUM(AA9,AP9,AZ9) -> 1 | BK9: =SUM(BH9:BJ9) -> 1
A10: 3권역 | B10: 미추홀구 | C10: 미추홀구 | D10: 도화2,3동 | E10: 공립 | F10: 인천서화초등학교병설유치원 | G10: 31837 | H10: 미추홀구 송림로 250(도화동 1003번지) | I10: 19126 | J10: 22114 | K10: 629-0957 | L10: 868-9237 | M10: 3 | O10: 48 | P10: 1 | Q10: 6 | R10: 1 | S10: 6 | T10: 1 | U10: 7 | AF10: =SUM(AD10:AE10) -> 0 | AI10: =SUM(AG10:AH10) -> 0 | AN10: =SUM(AL10:AM10) -> 0 | AQ10: =SUM(AO10:AP10) -> 0 | AW10: =SUM(AT10:AV10) -> 0 | BA10: =SUM(AX10:AZ10) -> 0 | BB10: =SUM(P10,R10,T10,AB10,AJ10,AR10) -> 3 | BC10: =SUM(Q10,AD10,AT10) -> 6 | BD10: =SUM(S10,AE10,AL10,AU10) -> 6 | BE10: =SUM(U10,AM10,AV10) -> 7 | BF10: =SUM(BC10:BE10) -> 19 | BG10: =SUM(V10,X10,Z10,AC10,AK10,AS10) -> 0 | BH10: =SUM(W10,AG10,AX10) -> 0 | BI10: =SUM(Y10,AH10,AO10,AY10) -> 0 | BJ10: =SUM(AA10,AP10,AZ10) -> 0 | BK10: =SUM(BH10:BJ10) -> 0
A11: 3권역 | B11: 미추홀구 | C11: 미추홀구 | D11: 숭의동 | E11: 공립 | F11: 인천숭의초등학교병설유치원 | G11: 34759 | H11: 미추홀구 장천로 99(숭의동42-2) | I11: 11060 | J11: 22163 | K11: 629-0290 | L11: 887-9017 | M11: 1 | O11: 19 | T11: 1 | U11: 17 | AF11: - | AI11: - | AN11: - | AQ11: - | AW11: - | BA11: - | BB11: 1 | BC11: - | BD11: - | BE11: 17 | BF11: 17 | BG11: - | BH11: - | BI11: - | BJ11: - | BK11: -
A12: 3권역 | B12: 미추홀구 | C12: 미추홀구 | D12: 학익동 | E12: 공립 | F12: 인천연학초등학교병설유치원 | G12: 43770 | H12: 미추홀구 주승로 20(학익동 29-2) | I12: 12588 | J12: 22222 | K12: 629-1124 | L12: 629-1156 | M12: 3 | N12: 0 | O12: 48 | P12: 1 | Q12: 8 | R12: 1 | S12: 11 | T12: 1 | U12: 14 | V12: 0 | W12: 0 | X12: 0 | Y12: 0 | Z12: 0 | AA12: 0 | AB12: 0 | AC12: 0 | AD12: 0 | AE12: 0 | AF12: =SUM(AD12:AE12) -> 0 | AG12: 0 | AH12: 0 | AI12: =SUM(AG12:AH12) -> 0 | AJ12: 0 | AK12: 0 | AL12: 0 | AM12: 0 | AN12: =SUM(AL12:AM12) -> 0 | AO12: 0 | AP12: 0 | AQ12: =SUM(AO12:AP12) -> 0 | AR12: 0 | AS12: 0 | AT12: 0 | AU12: 0 | AV12: 0 | AW12: =SUM(AT12:AV12) -> 0 | AX12: 0 | AY12: 0 | AZ12: 0 | BA12: =SUM(AX12:AZ12) -> 0 | BB12: =SUM(P12,R12,T12,AB12,AJ12,AR12) -> 3 | BC12: =SUM(Q12,AD12,AT12) -> 8 | BD12: =SUM(S12,AE12,AL12,AU12) -> 11 | BE12: =SUM(U12,AM12,AV12) -> 14 | BF12: =SUM(BC12:BE12) -> 33 | BG12: =SUM(V12,X12,Z12,AC12,AK12,AS12) -> 0 | BH12: =SUM(W12,AG12,AX12) -> 0 | BI12: =SUM(Y12,AH12,AO12,AY12) -> 0 | BJ12: =SUM(AA12,AP12,AZ12) -> 0 | BK12: =SUM(BH12:BJ12) -> 0
A13: 3권역 | B13: 미추홀구 | C13: 미추홀구 | D13: 용현동 | E13: 공립 | F13: 인천용일초등학교병설유치원 | G13: 34759 | H13: 미추홀구 인주대로 244 | I13: 15883 | J13: 22208 | K13: 629-0873 | L13: 629-0878 | M13: 2 | N13: 1 | O13: 36 | R13: 1 | S13: 3 | T13: 1 | U13: 7 | AF13: =SUM(AD13:AE13) -> 0 | AI13: =SUM(AG13:AH13) -> 0 | AN13: =SUM(AL13:AM13) -> 0 | AO13: 2 | AP13: 2 | AQ13: =SUM(AO13:AP13) -> 4 | AW13: =SUM(AT13:AV13) -> 0 | BA13: =SUM(AX13:AZ13) -> 0 | BB13: =SUM(P13,R13,T13,AB13,AJ13,AR13) -> 2 | BC13: =SUM(Q13,AD13,AT13) -> 0 | BD13: =SUM(S13,AE13,AL13,AU13) -> 3 | BE13: =SUM(U13,AM13,AV13) -> 7 | BF13: =SUM(BC13:BE13) -> 10 | BG13: 1 | BH13: =SUM(W13,AG13,AX13) -> 0 | BI13: =SUM(Y13,AH13,AO13,AY13) -> 2 | BJ13: =SUM(AA13,AP13,AZ13) -> 2 | BK13: =SUM(BH13:BJ13) -> 4
A14: 3권역 | B14: 미추홀구 | C14: 미추홀구 | D14: 숭의동 | E14: 공립 | F14: 인천용정초등학교병설유치원 | G14: 31826 | H14: 미추홀구 독정안길 26(숭의동 12-8) | I14: 12538 | J14: 22168 | K14: 629-0987 | L14: 876-6133 | M14: 1 | N14: 0 | O14: 19 | AF14: =SUM(AD14:AE14) -> 0 | AI14: =SUM(AG14:AH14) -> 0 | AJ14: 1 | AK14: 0 | AL14: 4 | AM14: 7 | AN14: =SUM(AL14:AM14) -> 11 | AO14: 0 | AQ14: =SUM(AO14:AP14) -> 0 | AW14: =SUM(AT14:AV14) -> 0 | BA14: =SUM(AX14:AZ14) -> 0 | BB14: =SUM(P14,R14,T14,AB14,AJ14,AR14) -> 1 | BC14: =SUM(Q14,AD14,AT14) -> 0 | BD14: =SUM(S14,AE14,AL14,AU14) -> 4 | BE14: =SUM(U14,AM14,AV14) -> 7 | BF14: =SUM(BC14:BE14) -> 11 | BG14: =SUM(V14,X14,Z14,AC14,AK14,AS14) -> 0 | BH14: =SUM(W14,AG14,AX14) -> 0 | BI14: =SUM(Y14,AH14,AO14,AY14) -> 0 | BJ14: =SUM(AA14,AP14,AZ14) -> 0 | BK14: =SUM(BH14:BJ14) -> 0
A15: 3권역 | B15: 미추홀구 | C15: 미추홀구 | D15: 용현동 | E15: 공립 | F15: 인천용학초등학교병설유치원 | G15: 42614 | H15: 미추홀구 용정공원로83번길 9(용현동 664-4) | I15: 11000 | J15: 22188 | K15: 627-6300 | L15: 886-9017 | M15: 5 | N15: 0 | O15: 84 | P15: 1 | Q15: 12 | R15: 2 | S15: 21 | T15: 2 | U15: 31 | V15: 0 | W15: 0 | X15: 0 | Y15: 0 | Z15: 0 | AA15: 0 | AB15: 0 | AC15: 0 | AD15: 0 | AE15: 0 | AF15: 0 | AG15: 0 | AH15: 0 | AI15: 0 | AJ15: 0 | AK15: 0 | AL15: 0 | AM15: 0 | AN15: 0 | AO15: 0 | AP15: 0 | AQ15: =SUM(AO15:AP15) -> 0 | AR15: 0 | AS15: 0 | AT15: 0 | AU15: 0 | AV15: 0 | AW15: =SUM(AT15:AV15) -> 0 | AX15: 0 | AY15: 0 | AZ15: 0 | BA15: =SUM(AX15:AZ15) -> 0 | BB15: =SUM(P15,R15,T15,AB15,AJ15,AR15) -> 5 | BC15: =SUM(Q15,AD15,AT15) -> 12 | BD15: =SUM(S15,AE15,AL15,AU15) -> 21 | BE15: =SUM(U15,AM15,AV15) -> 31 | BF15: =SUM(BC15:BE15) -> 64 | BG15: =SUM(V15,X15,Z15,AC15,AK15,AS15) -> 0 | BH15: =SUM(W15,AG15,AX15) -> 0 | BI15: =SUM(Y15,AH15,AO15,AY15) -> 0 | BJ15: =SUM(AA15,AP15,AZ15) -> 0 | BK15: =SUM(BH15:BJ15) -> 0
A16: 3권역 | B16: 미추홀구 | C16: 미추홀구 | D16: 학익2동 | E16: 공립 | F16: 인천인주초등학교병설유치원 | G16: 36586 | H16: 미추홀구 매소홀로475번길 53(학익동 40) | I16: 12756 | J16: 22222 | K16: 875-2606 | L16: 875-2602 | M16: 1 | O16: 19 | AF16: =SUM(AD16:AE16) -> 0 | AI16: =SUM(AG16:AH16) -> 0 | AN16: =SUM(AL16:AM16) -> 0 | AQ16: =SUM(AO16:AP16) -> 0 | AW16: =SUM(AT16:AV16) -> 0 | BA16: =SUM(AX16:AZ16) -> 0 | BB16: =SUM(P16,R16,T16,AB16,AJ16,AR16) -> 0 | BC16: =SUM(Q16,AD16,AT16) -> 0 | BD16: =SUM(S16,AE16,AL16,AU16) -> 0 | BE16: =SUM(U16,AM16,AV16) -> 0 | BF16: =SUM(BC16:BE16) -> 0 | BG16: =SUM(V16,X16,Z16,AC16,AK16,AS16) -> 0 | BH16: =SUM(W16,AG16,AX16) -> 0 | BI16: =SUM(Y16,AH16,AO16,AY16) -> 0 | BJ16: =SUM(AA16,AP16,AZ16) -> 0 | BK16: =SUM(BH16:BJ16) -> 0 | BL16: 휴원
A17: 3권역 | B17: 미추홀구 | C17: 미추홀구 | D17: 학익동 | E17: 공립 | F17: 인천학익초등학교병설유치원 | G17: 31853 | H17: 미추홀구 한나루로 403번길 122(학익동 330-1번지) | I17: 13126 | J17: 22211 | K17: 629-0428 | L17: 865-5795 | M17: 2 | N17: 1 | O17: 36 | T17: 1 | U17: 3 | AB17: 1 | AE17: 6 | AF17: =SUM(AD17:AE17) -> 6 | AS17: 1 | AY17: 1 | AZ17: 3 | BA17: =SUM(AX17:AZ17) -> 4 | BB17: =SUM(P17,R17,T17,AB17,AJ17,AR17) -> 2 | BC17: =SUM(Q17,AD17,AT17) -> 0 | BD17: =SUM(S17,AE17,AL17,AU17) -> 6 | BE17: =SUM(U17,AM17,AV17) -> 3 | BF17: =SUM(BC17:BE17) -> 9 | BG17: =SUM(V17,X17,Z17,AC17,AK17,AS17) -> 1 | BH17: =SUM(W17,AG17,AX17) -> 0 | BI17: =SUM(Y17,AH17,AO17,AY17) -> 1 | BJ17: =SUM(AA17,AP17,AZ17) -> 3 | BK17: =SUM(BH17:BJ17) -> 4
A18: 4권역 | B18: 미추홀구 | C18: 미추홀구 | D18: 주안6동 | E18: 공립 | F18: 인천경원초등학교병설유치원 | G18: 39508 | H18: 미추홀구 경인로 511(주안동1620) | I18: 5786 | J18: 22144 | K18: 629-2142 | L18: 424-1693 | M18: 2 | O18: 36 | T18: 1 | U18: 4 | AB18: 1 | AD18: 3 | AE18: 1 | AF18: =SUM(AD18:AE18) -> 4 | AI18: =SUM(AG18:AH18) -> 0 | AN18: =SUM(AL18:AM18) -> 0 | AQ18: =SUM(AO18:AP18) -> 0 | AW18: =SUM(AT18:AV18) -> 0 | BA18: =SUM(AX18:AZ18) -> 0 | BB18: =SUM(P18,R18,T18,AB18,AJ18,AR18) -> 2 | BC18: =SUM(Q18,AD18,AT18) -> 3 | BD18: =SUM(S18,AE18,AL18,AU18) -> 1 | BE18: =SUM(U18,AM18,AV18) -> 4 | BF18: =SUM(BC18:BE18) -> 8 | BG18: =SUM(V18,X18,Z18,AC18,AK18,AS18) -> 0 | BH18: =SUM(W18,AG18,AX18) -> 0 | BI18: =SUM(Y18,AH18,AO18,AY18) -> 0 | BJ18: =SUM(AA18,AP18,AZ18) -> 0 | BK18: =SUM(BH18:BJ18) -> 0
A19: 4권역 | B19: 미추홀구 | C19: 미추홀구 | D19: 문학동 | E19: 공립 | F19: 인천문학초등학교병설유치원 | G19: 35490 | H19: 미추홀구 매소홀로 553(문학동 343-2) | I19: 875 | J19: 22233 | K19: 629-0153 | L19: 433-0367 | M19: 2 | O19: 36 | AF19: =SUM(AD19:AE19) -> 0 | AI19: =SUM(AG19:AH19) -> 0 | AN19: =SUM(AL19:AM19) -> 0 | AQ19: =SUM(AO19:AP19) -> 0 | AR19: 1 | AT19: 0 | AU19: 1 | AV19: 5 | AW19: =SUM(AT19:AV19) -> 6 | BA19: =SUM(AX19:AZ19) -> 0 | BB19: =SUM(P19,R19,T19,AB19,AJ19,AR19) -> 1 | BC19: =SUM(Q19,AD19,AT19) -> 0 | BD19: =SUM(S19,AE19,AL19,AU19) -> 1 | BE19: =SUM(U19,AM19,AV19) -> 5 | BF19: =SUM(BC19:BE19) -> 6 | BG19: =SUM(V19,X19,Z19,AC19,AK19,AS19) -> 0 | BH19: =SUM(W19,AG19,AX19) -> 0 | BI19: =SUM(Y19,AH19,AO19,AY19) -> 0 | BJ19: =SUM(AA19,AP19,AZ19) -> 0 | BK19: =SUM(BH19:BJ19) -> 0
A20: 4권역 | B20: 미추홀구 | C20: 미추홀구 | D20: 주안동 | E20: 공립 | F20: 인천주안초등학교병설유치원 | G20: 43160 | H20: 미추홀구 남주길69번길 16(주안동 1627) | I20: 16925 | J20: 22156 | K20: 458-9919 | L20: 438-1405 | M20: 3 | N20: 1 | O20: 48 | P20: 1 | Q20: 3 | R20: 1 | S20: 9 | T20: 1 | U20: 17 | AF20: =SUM(AD20:AE20) -> 0 | AI20: =SUM(AG20:AH20) -> 0 | AN20: =SUM(AL20:AM20) -> 0 | AS20: 1 | AW20: =SUM(AT20:AV20) -> 0 | AY20: 2 | AZ20: 2 | BA20: =SUM(AX20:AZ20) -> 4 | BB20: =SUM(P20,R20,T20,AB20,AJ20,AR20) -> 3 | BC20: =SUM(Q20,AD20,AT20) -> 3 | BD20: =SUM(S20,AE20,AL20,AU20) -> 9 | BE20: =SUM(U20,AM20,AV20) -> 17 | BF20: =SUM(BC20:BE20) -> 29 | BG20: =SUM(V20,X20,Z20,AC20,AK20,AS20) -> 1 | BH20: =SUM(W20,AG20,AX20) -> 0 | BI20: 2 | BJ20: 2 | BK20: =SUM(BH20:BJ20) -> 4
A21: 미추홀구 공립 계 | E21: =COUNTA(E8:E20) -> 13 | M21: =SUM(M8:M20) -> 29 | N21: =SUM(N8:N20) -> 4 | O21: =SUM(O8:O20) -> 501 | P21: =SUM(P8:P20) -> 4 | Q21: =SUM(Q8:Q20) -> 29 | R21: =SUM(R8:R20) -> 6 | S21: =SUM(S8:S20) -> 50 | T21: =SUM(T8:T20) -> 11 | ... BK21: =SUM(BK8:BK20) -> 13
A22: 3권역 | B22: 미추홀구 | C22: 미추홀구 | D22: 도화1동 | E22: 사립 | F22: 프라임건영유치원 | G22: 42552 | H22: 미추홀구 남주길11번길79(도화동 463-6) | I22: 695 | J22: 22153 | K22: 863-6854 | L22: 714-3795 | M22: 7 | O22: 122 | P22: 2 | Q22: 25 | R22: 1 | S22: 22 | T22: 2 | U22: 34 | AF22: =SUM(AD22:AE22) -> 0 | AI22: =SUM(AG22:AH22) -> 0 | AN22: =SUM(AL22:AM22) -> 0 | AQ22: =SUM(AO22:AP22) -> 0 | AW22: =SUM(AT22:AV22) -> 0 | BA22: =SUM(AX22:AZ22) -> 0 | BB22: =SUM(P22,R22,T22,AB22,AJ22,AR22) -> 5 | BC22: =SUM(Q22,AD22,AT22) -> 25 | BD22: =SUM(S22,AE22,AL22,AU22) -> 22 | BE22: =SUM(U22,AM22,AV22) -> 34 | BF22: =SUM(BC22:BE22) -> 81 | BG22: =SUM(V22,X22,Z22,AC22,AK22,AS22) -> 0 | BH22: =SUM(W22,AG22,AX22) -> 0 | BI22: =SUM(Y22,AH22,AO22,AY22) -> 0 | BJ22: =SUM(AA22,AP22,AZ22) -> 0 | BK22: =SUM(BH22:BJ22) -> 0
A23: 3권역 | B23: 미추홀구 | C23: 미추홀구 | D23: 도화2,3동 | E23: 사립 | F23: 밀알유치원 | G23: 46082 | H23: 미추홀구 장고개로 42번길 42(도화동 119-16) | I23: 1625 | J23: 22116 | K23: 876-3313 | L23: 715-7813 | M23: 9 | O23: 221 | P23: 3 | Q23: 47 | R23: 3 | S23: 73 | T23: 3 | U23: 77 | AF23: =SUM(AD23:AE23) -> 0 | AI23: =SUM(AG23:AH23) -> 0 | AN23: =SUM(AL23:AM23) -> 0 | AQ23: =SUM(AO23:AP23) -> 0 | AW23: =SUM(AT23:AV23) -> 0 | BA23: =SUM(AX23:AZ23) -> 0 | BB23: =SUM(P23,R23,T23,AB23,AJ23,AR23) -> 9 | BC23: =SUM(Q23,AD23,AT23) -> 47 | BD23: =SUM(S23,AE23,AL23,AU23) -> 73 | BE23: =SUM(U23,AM23,AV23) -> 77 | BF23: =SUM(BC23:BE23) -> 197 | BG23: =SUM(V23,X23,Z23,AC23,AK23,AS23) -> 0 | BH23: =SUM(W23,AG23,AX23) -> 0 | BI23: =SUM(Y23,AH23,AO23,AY23) -> 0 | BJ23: =SUM(AA23,AP23,AZ23) -> 0 | BK23: =SUM(BH23:BJ23) -> 0
A24: 3권역 | B24: 미추홀구 | C24: 미추홀구 | D24: 숭의2동 | E24: 사립 | F24: 숭의유치원 | G24: 24152 | H24: 미추홀구구 독배로 485(숭의동 303-7) | I24: 415 | J24: 22173 | K24: 885-3399 | L24: 885-3343 | M24: 4 | O24: 88 | P24: 1 | Q24: 18 | R24: 2 | S24: 44 | T24: 1 | U24: 26 | AF24: =SUM(AD24:AE24) -> 0 | AI24: =SUM(AG24:AH24) -> 0 | AN24: =SUM(AL24:AM24) -> 0 | AQ24: =SUM(AO24:AP24) -> 0 | AW24: =SUM(AT24:AV24) -> 0 | BA24: =SUM(AX24:AZ24) -> 0 | BB24: =SUM(P24,R24,T24,AB24,AJ24,AR24) -> 4 | BC24: =SUM(Q24,AD24,AT24) -> 18 | BD24: =SUM(S24,AE24,AL24,AU24) -> 44 | BE24: =SUM(U24,AM24,AV24) -> 26 | BF24: =SUM(BC24:BE24) -> 88 | BG24: =SUM(V24,X24,Z24,AC24,AK24,AS24) -> 0 | BH24: =SUM(W24,AG24,AX24) -> 0 | BI24: =SUM(Y24,AH24,AO24,AY24) -> 0 | BJ24: =SUM(AA24,AP24,AZ24) -> 0 | BK24: =SUM(BH24:BJ24) -> 0
A25: 3권역 | B25: 미추홀구 | C25: 미추홀구 | D25: 용현1,4동 | E25: 사립 | F25: 성바오로유치원 | G25: 33304 | H25: 미추홀구 경인남길 102번길 50(용현동 183-15) | I25: 1491 | J25: 22207 | K25: 875-6204 | L25: 875-6205 | M25: 6 | O25: 210 | AF25: =SUM(AD25:AE25) -> 0 | AI25: =SUM(AG25:AH25) -> 0 | AN25: =SUM(AL25:AM25) -> 0 | AQ25: =SUM(AO25:AP25) -> 0 | AR25: 6 | AT25: 37 | AU25: 41 | AV25: 45 | AW25: =SUM(AT25:AV25) -> 123 | BA25: =SUM(AX25:AZ25) -> 0 | BB25: =SUM(P25,R25,T25,AB25,AJ25,AR25) -> 6 | BC25: =SUM(Q25,AD25,AT25) -> 37 | BD25: =SUM(S25,AE25,AL25,AU25) -> 41 | BE25: =SUM(U25,AM25,AV25) -> 45 | BF25: =SUM(BC25:BE25) -> 123 | BG25: =SUM(V25,X25,Z25,AC25,AK25,AS25) -> 0 | BH25: =SUM(W25,AG25,AX25) -> 0 | BI25: =SUM(Y25,AH25,AO25,AY25) -> 0 | BJ25: =SUM(AA25,AP25,AZ25) -> 0 | BK25: =SUM(BH25:BJ25) -> 0
A26: 3권역 | B26: 미추홀구 | C26: 미추홀구 | D26: 용현2동 | E26: 사립 | F26: 유원유치원 | G26: 33264 | H26: 미추홀구 낙섬중로 102(용현동 557-1) | I26: 468 | J26: 22185 | K26: 883-9591 | L26: 0504-213-5580 | M26: 4 | O26: 95 | P26: 1 | Q26: 14 | R26: 1 | S26: 24 | T26: 2 | U26: 45 | AF26: =SUM(AD26:AE26) -> 0 | AI26: =SUM(AG26:AH26) -> 0 | AN26: =SUM(AL26:AM26) -> 0 | AQ26: =SUM(AO26:AP26) -> 0 | AW26: =SUM(AT26:AV26) -> 0 | BA26: =SUM(AX26:AZ26) -> 0 | BB26: =SUM(P26,R26,T26,AB26,AJ26,AR26) -> 4 | BC26: =SUM(Q26,AD26,AT26) -> 14 | BD26: =SUM(S26,AE26,AL26,AU26) -> 24 | BE26: =SUM(U26,AM26,AV26) -> 45 | BF26: =SUM(BC26:BE26) -> 83 | BG26: =SUM(V26,X26,Z26,AC26,AK26,AS26) -> 0 | BH26: =SUM(W26,AG26,AX26) -> 0 | BI26: =SUM(Y26,AH26,AO26,AY26) -> 0 | BJ26: =SUM(AA26,AP26,AZ26) -> 0 | BK26: =SUM(BH26:BJ26) -> 0
A27: 3권역 | B27: 미추홀구 | C27: 미추홀구 | D27: 용현5동 | E27: 사립 | F27: 금호유치원 | G27: 36951 | H27: 미추홀구 매소홀로 54(용현동 647-1) | I27: 666 | J27: 22192 | K27: 891-0188 | L27: 891-0189 | M27: 7 | O27: 142 | P27: 3 | Q27: 49 | R27: 2 | S27: 47 | T27: 2 | U27: 46 | AF27: =SUM(AD27:AE27) -> 0 | AI27: =SUM(AG27:AH27) -> 0 | AN27: =SUM(AL27:AM27) -> 0 | AQ27: =SUM(AO27:AP27) -> 0 | AW27: =SUM(AT27:AV27) -> 0 | BA27: =SUM(AX27:AZ27) -> 0 | BB27: =SUM(P27,R27,T27,AB27,AJ27,AR27) -> 7 | BC27: =SUM(Q27,AD27,AT27) -> 49 | BD27: =SUM(S27,AE27,AL27,AU27) -> 47 | BE27: =SUM(U27,AM27,AV27) -> 46 | BF27: =SUM(BC27:BE27) -> 142 | BG27: =SUM(V27,X27,Z27,AC27,AK27,AS27) -> 0 | BH27: =SUM(W27,AG27,AX27) -> 0 | BI27: =SUM(Y27,AH27,AO27,AY27) -> 0 | BJ27: =SUM(AA27,AP27,AZ27) -> 0 | BK27: =SUM(BH27:BJ27) -> 0
A28: 3권역 | B28: 미추홀구 | C28: 미추홀구 | D28: 용현5동 | E28: 사립 | F28: 노벨유치원 | G28: 32520 | H28: 미추홀구 낙섬중로 74(용현동 577-58) | I28: 206 | J28: 22187 | K28: 884-1059 | L28: 888-7400 | M28: 3 | O28: 105 | P28: 1 | Q28: 19 | R28: 1 | S28: 20 | T28: 1 | U28: 25 | AF28: =SUM(AD28:AE28) -> 0 | AI28: =SUM(AG28:AH28) -> 0 | AN28: =SUM(AL28:AM28) -> 0 | AQ28: =SUM(AO28:AP28) -> 0 | AW28: =SUM(AT28:AV28) -> 0 | BA28: =SUM(AX28:AZ28) -> 0 | BB28: =SUM(P28,R28,T28,AB28,AJ28,AR28) -> 3 | BC28: =SUM(Q28,AD28,AT28) -> 19 | BD28: =SUM(S28,AE28,AL28,AU28) -> 20 | BE28: =SUM(U28,AM28,AV28) -> 25 | BF28: =SUM(BC28:BE28) -> 64 | BG28: =SUM(V28,X28,Z28,AC28,AK28,AS28) -> 0 | BH28: =SUM(W28,AG28,AX28) -> 0 | BI28: =SUM(Y28,AH28,AO28,AY28) -> 0 | BJ28: =SUM(AA28,AP28,AZ28) -> 0 | BK28: =SUM(BH28:BJ28) -> 0
A29: 3권역 | B29: 미추홀구 | C29: 미추홀구 | D29: 용현5동 | E29: 사립 | F29: 세종유치원 | G29: 32568 | H29: 미추홀구 낙섬서로 77(용현동 624-77) | I29: 274.1 | J29: 22186 | K29: 888-3456 | L29: 888-3600 | M29: 4 | O29: 107 | P29: 1 | Q29: 23 | R29: 1 | S29: 28 | T29: 2 | U29: 55 | AF29: =SUM(AD29:AE29) -> 0 | AI29: =SUM(AG29:AH29) -> 0 | AN29: =SUM(AL29:AM29) -> 0 | AQ29: =SUM(AO29:AP29) -> 0 | AW29: =SUM(AT29:AV29) -> 0 | BA29: =SUM(AX29:AZ29) -> 0 | BB29: =SUM(P29,R29,T29,AB29,AJ29,AR29) -> 4 | BC29: =SUM(Q29,AD29,AT29) -> 23 | BD29: =SUM(S29,AE29,AL29,AU29) -> 28 | BE29: =SUM(U29,AM29,AV29) -> 55 | BF29: =SUM(BC29:BE29) -> 106 | BG29: =SUM(V29,X29,Z29,AC29,AK29,AS29) -> 0 | BH29: =SUM(W29,AG29,AX29) -> 0 | BI29: =SUM(Y29,AH29,AO29,AY29) -> 0 | BJ29: =SUM(AA29,AP29,AZ29) -> 0 | BK29: =SUM(BH29:BJ29) -> 0
A30: 3권역 | B30: 미추홀구 | C30: 미추홀구 | D30: 용현5동 | E30: 사립 | F30: 소명유치원 | G30: 32507 | H30: 미추홀구 낙섬동로 71-1(용현동 611-75) | I30: 916 | J30: 22187 | K30: 884-7780 | L30: 891-3600 | M30: 7 | O30: 180 | P30: 3 | Q30: 61 | R30: 2 | S30: 47 | T30: 2 | U30: 55 | AF30: =SUM(AD30:AE30) -> 0 | AI30: =SUM(AG30:AH30) -> 0 | AN30: =SUM(AL30:AM30) -> 0 | AQ30: =SUM(AO30:AP30) -> 0 | AW30: =SUM(AT30:AV30) -> 0 | BA30: =SUM(AX30:AZ30) -> 0 | BB30: =SUM(P30,R30,T30,AB30,AJ30,AR30) -> 7 | BC30: =SUM(Q30,AD30,AT30) -> 61 | BD30: =SUM(S30,AE30,AL30,AU30) -> 47 | BE30: =SUM(U30,AM30,AV30) -> 55 | BF30: =SUM(BC30:BE30) -> 163 | BG30: =SUM(V30,X30,Z30,AC30,AK30,AS30) -> 0 | BH30: =SUM(W30,AG30,AX30) -> 0 | BI30: =SUM(Y30,AH30,AO30,AY30) -> 0 | BJ30: =SUM(AA30,AP30,AZ30) -> 0 | BK30: =SUM(BH30:BJ30) -> 0
A31: 3권역 | B31: 미추홀구 | C31: 미추홀구 | D31: 학익1동 | E31: 사립 | F31: 반디유치원 | G31: 39508 | H31: 미추홀구 매소홀로 340(학익동 721) | I31: 510 | J31: 22203 | K31: 875-6767 | L31: 875-6787 | M31: 6 | O31: 171 | P31: 2 | Q31: 41 | R31: 2 | S31: 52 | T31: 2 | U31: 56 | AF31: =SUM(AD31:AE31) -> 0 | AI31: =SUM(AG31:AH31) -> 0 | AN31: =SUM(AL31:AM31) -> 0 | AQ31: =SUM(AO31:AP31) -> 0 | AW31: =SUM(AT31:AV31) -> 0 | BA31: =SUM(AX31:AZ31) -> 0 | BB31: =SUM(P31,R31,T31,AB31,AJ31,AR31) -> 6 | BC31: =SUM(Q31,AD31,AT31) -> 41 | BD31: =SUM(S31,AE31,AL31,AU31) -> 52 | BE31: =SUM(U31,AM31,AV31) -> 56 | BF31: =SUM(BC31:BE31) -> 149 | BG31: =SUM(V31,X31,Z31,AC31,AK31,AS31) -> 0 | BH31: =SUM(W31,AG31,AX31) -> 0 | BI31: =SUM(Y31,AH31,AO31,AY31) -> 0 | BJ31: =SUM(AA31,AP31,AZ31) -> 0 | BK31: =SUM(BH31:BJ31) -> 0
A32: 3권역 | B32: 미추홀구 | C32: 미추홀구 | D32: 학익1동 | E32: 사립 | F32: 한빛유치원 | G32: 40997 | H32: 미추홀구 소성로 120(학익동 719) | I32: 759 | J32: 22202 | K32: 875-8008 | L32: 875-8112 | M32: 6 | O32: 134 | P32: 2 | Q32: 39 | R32: 2 | S32: 46 | T32: 2 | U32: 48 | AF32: =SUM(AD32:AE32) -> 0 | AI32: =SUM(AG32:AH32) -> 0 | AN32: =SUM(AL32:AM32) -> 0 | AQ32: =SUM(AO32:AP32) -> 0 | AW32: =SUM(AT32:AV32) -> 0 | BA32: =SUM(AX32:AZ32) -> 0 | BB32: =SUM(P32,R32,T32,AB32,AJ32,AR32) -> 6 | BC32: =SUM(Q32,AD32,AT32) -> 39 | BD32: =SUM(S32,AE32,AL32,AU32) -> 46 | BE32: =SUM(U32,AM32,AV32) -> 48 | BF32: =SUM(BC32:BE32) -> 133 | BG32: =SUM(V32,X32,Z32,AC32,AK32,AS32) -> 0 | BH32: =SUM(W32,AG32,AX32) -> 0 | BI32: =SUM(Y32,AH32,AO32,AY32) -> 0 | BJ32: =SUM(AA32,AP32,AZ32) -> 0 | BK32: =SUM(BH32:BJ32) -> 0
A33: 3권역 | B33: 미추홀구 | C33: 미추홀구 | D33: 학익2동 | E33: 사립 | F33: 다솜유치원 | G33: 32568 | H33: 인천시 미추홀구 학익소로 23번길 11(학익동 15-5) | I33: 508 | J33: 22218 | K33: 862-1600 | L33: 874-9596 | M33: 7 | O33: 280 | P33: 1 | Q33: 14 | R33: 1 | S33: 16 | T33: 1 | U33: 16 | AF33: =SUM(AD33:AE33) -> 0 | AI33: =SUM(AG33:AH33) -> 0 | AN33: =SUM(AL33:AM33) -> 0 | AQ33: =SUM(AO33:AP33) -> 0 | AW33: =SUM(AT33:AV33) -> 0 | BA33: =SUM(AX33:AZ33) -> 0 | BB33: =SUM(P33,R33,T33,AB33,AJ33,AR33) -> 3 | BC33: =SUM(Q33,AD33,AT33) -> 14 | BD33: =SUM(S33,AE33,AL33,AU33) -> 16 | BE33: =SUM(U33,AM33,AV33) -> 16 | BF33: =SUM(BC33:BE33) -> 46 | BG33: =SUM(V33,X33,Z33,AC33,AK33,AS33) -> 0 | BH33: =SUM(W33,AG33,AX33) -> 0 | BI33: =SUM(Y33,AH33,AO33,AY33) -> 0 | BJ33: =SUM(AA33,AP33,AZ33) -> 0 | BK33: =SUM(BH33:BJ33) -> 0
A34: 3권역 | B34: 미추홀구 | C34: 미추홀구 | D34: 학익2동 | E34: 사립 | F34: 신동아유치원 | G34: 34029 | H34: 미추홀구 매소홀로475번길 18(학익동 48-14) | I34: 508 | J34: 22222 | K34: 872-4348 | L34: 872-4349 | M34: 4 | O34: 150 | AF34: =SUM(AD34:AE34) -> 0 | AI34: =SUM(AG34:AH34) -> 0 | AN34: =SUM(AL34:AM34) -> 0 | AQ34: =SUM(AO34:AP34) -> 0 | AW34: =SUM(AT34:AV34) -> 0 | BA34: =SUM(AX34:AZ34) -> 0 | BB34: =SUM(P34,R34,T34,AB34,AJ34,AR34) -> 0 | BC34: =SUM(Q34,AD34,AT34) -> 0 | BD34: =SUM(S34,AE34,AL34,AU34) -> 0 | BE34: =SUM(U34,AM34,AV34) -> 0 | BF34: =SUM(BC34:BE34) -> 0 | BG34: =SUM(V34,X34,Z34,AC34,AK34,AS34) -> 0 | BH34: =SUM(W34,AG34,AX34) -> 0 | BI34: =SUM(Y34,AH34,AO34,AY34) -> 0 | BJ34: =SUM(AA34,AP34,AZ34) -> 0 | BK34: =SUM(BH34:BJ34) -> 0 | BL34: 휴원
A35: 3권역 | B35: 미추홀구 | C35: 미추홀구 | D35: 학익2동 | E35: 사립 | F35: 해승유치원 | G35: 34821 | H35: 미추홀구 학익소로61번길 93(학익동 645) | I35: 388 | J35: 22222 | K35: 872-4626 | L35: 872-4627 | M35: 4 | O35: 120 | P35: 1 | Q35: 22 | R35: 1 | S35: 25 | T35: 2 | U35: 50 | AF35: =SUM(AD35:AE35) -> 0 | AI35: =SUM(AG35:AH35) -> 0 | AN35: =SUM(AL35:AM35) -> 0 | AQ35: =SUM(AO35:AP35) -> 0 | AW35: =SUM(AT35:AV35) -> 0 | BA35: =SUM(AX35:AZ35) -> 0 | BB35: =SUM(P35,R35,T35,AB35,AJ35,AR35) -> 4 | BC35: =SUM(Q35,AD35,AT35) -> 22 | BD35: =SUM(S35,AE35,AL35,AU35) -> 25 | BE35: =SUM(U35,AM35,AV35) -> 50 | BF35: =SUM(BC35:BE35) -> 97 | BG35: =SUM(V35,X35,Z35,AC35,AK35,AS35) -> 0 | BH35: =SUM(W35,AG35,AX35) -> 0 | BI35: =SUM(Y35,AH35,AO35,AY35) -> 0 | BJ35: =SUM(AA35,AP35,AZ35) -> 0 | BK35: =SUM(BH35:BJ35) -> 0
A36: 4권역 | B36: 미추홀구 | C36: 미추홀구 | D36: 문학동 | E36: 사립 | F36: 그림나라유치원 | G36: 39143 | H36: 미추홀구 소성로332번길 10(문학동 374-3) | I36: 461 | J36: 22238 | K36: 424-4088 | L36: 424-4089 | M36: 6 | O36: 160 | P36: 2 | Q36: 16 | R36: 2 | S36: 39 | T36: 2 | U36: 34 | AF36: =SUM(AD36:AE36) -> 0 | AI36: =SUM(AG36:AH36) -> 0 | AN36: =SUM(AL36:AM36) -> 0 | AQ36: =SUM(AO36:AP36) -> 0 | AW36: =SUM(AT36:AV36) -> 0 | BA36: =SUM(AX36:AZ36) -> 0 | BB36: =SUM(P36,R36,T36,AB36,AJ36,AR36) -> 6 | BC36: =SUM(Q36,AD36,AT36) -> 16 | BD36: =SUM(S36,AE36,AL36,AU36) -> 39 | BE36: =SUM(U36,AM36,AV36) -> 34 | BF36: =SUM(BC36:BE36) -> 89 | BG36: =SUM(V36,X36,Z36,AC36,AK36,AS36) -> 0 | BH36: =SUM(W36,AG36,AX36) -> 0 | BI36: =SUM(Y36,AH36,AO36,AY36) -> 0 | BJ36: =SUM(AA36,AP36,AZ36) -> 0 | BK36: =SUM(BH36:BJ36) -> 0
A37: 4권역 | B37: 미추홀구 | C37: 미추홀구 | D37: 주안2동 | E37: 사립 | F37: 참빛유치원 | G37: 39508 | H37: 미추홀구 수봉로 135번길 29(주안2동 660-168) | I37: 782 | J37: 22166 | K37: 882-9371 | L37: 881-9371 | M37: 6 | O37: 144 | P37: 1 | Q37: 11 | R37: 2 | S37: 28 | T37: 2 | U37: 26 | AF37: =SUM(AD37:AE37) -> 0 | AI37: =SUM(AG37:AH37) -> 0 | AN37: =SUM(AL37:AM37) -> 0 | AQ37: =SUM(AO37:AP37) -> 0 | AW37: =SUM(AT37:AV37) -> 0 | BA37: =SUM(AX37:AZ37) -> 0 | BB37: =SUM(P37,R37,T37,AB37,AJ37,AR37) -> 5 | BC37: =SUM(Q37,AD37,AT37) -> 11 | BD37: =SUM(S37,AE37,AL37,AU37) -> 28 | BE37: =SUM(U37,AM37,AV37) -> 26 | BF37: =SUM(BC37:BE37) -> 65 | BG37: =SUM(V37,X37,Z37,AC37,AK37,AS37) -> 0 | BH37: =SUM(W37,AG37,AX37) -> 0 | BI37: =SUM(Y37,AH37,AO37,AY37) -> 0 | BJ37: =SUM(AA37,AP37,AZ37) -> 0 | BK37: =SUM(BH37:BJ37) -> 0
A38: 4권역 | B38: 미추홀구 | C38: 미추홀구 | D38: 주안3동 | E38: 사립 | F38: 건영유치원 | G38: 40974 | H38: 미추홀구 인하로221번길 19(주안동 1418-126) | I38: 716 | J38: 22213 | K38: 866-6854 | L38: 714-3795 | M38: 10 | O38: 215 | P38: 4 | Q38: 57 | R38: 3 | S38: 49 | T38: 3 | U38: 63 | AF38: =SUM(AD38:AE38) -> 0 | AI38: =SUM(AG38:AH38) -> 0 | AN38: =SUM(AL38:AM38) -> 0 | AQ38: =SUM(AO38:AP38) -> 0 | AW38: =SUM(AT38:AV38) -> 0 | BA38: =SUM(AX38:AZ38) -> 0 | BB38: =SUM(P38,R38,T38,AB38,AJ38,AR38) -> 10 | BC38: =SUM(Q38,AD38,AT38) -> 57 | BD38: =SUM(S38,AE38,AL38,AU38) -> 49 | BE38: =SUM(U38,AM38,AV38) -> 63 | BF38: =SUM(BC38:BE38) -> 169 | BG38: =SUM(V38,X38,Z38,AC38,AK38,AS38) -> 0 | BH38: =SUM(W38,AG38,AX38) -> 0 | BI38: =SUM(Y38,AH38,AO38,AY38) -> 0 | BJ38: =SUM(AA38,AP38,AZ38) -> 0 | BK38: =SUM(BH38:BJ38) -> 0
A39: 4권역 | B39: 미추홀구 | C39: 미추홀구 | D39: 주안3동 | E39: 사립 | F39: 동원유치원 | G39: 29646 | H39: 미추홀구 인하로235번길 27(주안동 1420-32) | I39: 864 | J39: 22214 | K39: 866-2657 | L39: 876-2657 | M39: 7 | O39: 270 | P39: 2 | Q39: 48 | R39: 3 | S39: 61 | T39: 2 | U39: 57 | AF39: =SUM(AD39:AE39) -> 0 | AI39: =SUM(AG39:AH39) -> 0 | AN39: =SUM(AL39:AM39) -> 0 | AQ39: =SUM(AO39:AP39) -> 0 | AW39: =SUM(AT39:AV39) -> 0 | BA39: =SUM(AX39:AZ39) -> 0 | BB39: =SUM(P39,R39,T39,AB39,AJ39,AR39) -> 7 | BC39: =SUM(Q39,AD39,AT39) -> 48 | BD39: =SUM(S39,AE39,AL39,AU39) -> 61 | BE39: =SUM(U39,AM39,AV39) -> 57 | BF39: =SUM(BC39:BE39) -> 166 | BG39: =SUM(V39,X39,Z39,AC39,AK39,AS39) -> 0 | BH39: =SUM(W39,AG39,AX39) -> 0 | BI39: =SUM(Y39,AH39,AO39,AY39) -> 0 | BJ39: =SUM(AA39,AP39,AZ39) -> 0 | BK39: =SUM(BH39:BJ39) -> 0
A40: 4권역 | B40: 미추홀구 | C40: 미추홀구 | D40: 주안4동 | E40: 사립 | F40: 소라유치원 | G40: 29646 | H40: 미추홀구 경원대로 799(주안동 253-14) | I40: 943 | J40: 22150 | K40: 424-2364 | L40: 434-2172 | M40: 8 | O40: 300 | AF40: =SUM(AD40:AE40) -> 0 | AI40: =SUM(AG40:AH40) -> 0 | AN40: =SUM(AL40:AM40) -> 0 | AQ40: =SUM(AO40:AP40) -> 0 | AW40: =SUM(AT40:AV40) -> 0 | BA40: =SUM(AX40:AZ40) -> 0 | BB40: =SUM(P40,R40,T40,AB40,AJ40,AR40) -> 0 | BC40: =SUM(Q40,AD40,AT40) -> 0 | BD40: =SUM(S40,AE40,AL40,AU40) -> 0 | BE40: =SUM(U40,AM40,AV40) -> 0 | BF40: =SUM(BC40:BE40) -> 0 | BG40: =SUM(V40,X40,Z40,AC40,AK40,AS40) -> 0 | BH40: =SUM(W40,AG40,AX40) -> 0 | BI40: =SUM(Y40,AH40,AO40,AY40) -> 0 | BJ40: =SUM(AA40,AP40,AZ40) -> 0 | BK40: =SUM(BH40:BJ40) -> 0 | BL40: 휴원
...

Sheet 초등학교
A1: □ 초등학교 현황
A2: ▶ 작성기준일: 2026. 4. 1.자
A3: 교육지원청 | B3: 구군별 | C3: 개편후 행정구역(2026.7.1.시행) | D3: 설립별 | E3: 학교명 | F3: 개교일자 | G3: 주소 | H3: 교지면적(㎡) | I3: 우편번호 | J3: 전화번호 (교무실) | K3: 전화번호 (행정실) | L3: 팩스번호 (대표) | M3: 학급수 | V3: 총 학생수 | AJ3: 특수학급 학생수 | AL3: 한국어학급 학생수 | AN3: 비고
V4: 1학년 | X4: 2학년 | Z4: 3학년 | AB4: 4학년 | AD4: 5학년 | AF4: 6학년 | AH4: 합계
M5: 1학년 | N5: 2학년 | O5: 3학년 | P5: 4학년 | Q5: 5학년 | R5: 6학년 | S5: 특수 | T5: 한국어 | U5: 계 | V5: 계 | W5: 여 | X5: 계 | Y5: 여 | Z5: 계 | AA5: 여 | AB5: 계 | AC5: 여 | AD5: 계 | AE5: 여 | AF5: 계 | AG5: 여 | AH5: 계 | AI5: 여 | AJ5: 계 | AK5: 여 | AL5: 계 | AM5: 여
A6: 남부 | B6: 미추홀구 | C6: 미추홀구 | D6: 공립 | E6: 인천경원초등학교 | F6: 39508 | G6: 미추홀구 경인로 511(주안동 1620) | H6: 10201.1 | I6: 22144 | J6: 438-9321 | K6: 424-1692 | L6: 438-9324 | M6: 4 | N6: 5 | O6: 6 | P6: 7 | Q6: 6 | R6: 7 | S6: 2 | T6: 0 | U6: =SUM(M6:T6) -> 37 | V6: 102 | W6: 51 | X6: 125 | Y6: 53 | Z6: 148 | AA6: 71 | AB6: 162 | AC6: 82 | AD6: 150 | AE6: 63 | AF6: 169 | AG6: 77 | AH6: =V6+X6+Z6+AB6+AD6+AF6 -> 856 | AI6: =W6+Y6+AA6+AC6+AE6+AG6 -> 397 | AJ6: 10 | AK6: 10 | AL6: 0 | AM6: 0
A7: 남부 | B7: 미추홀구 | C7: 미추홀구 | D7: 공립 | E7: 인천관교초등학교 | F7: 31837 | G7: 미추홀구 인하로 414(관교동 334) | H7: 12563.7 | I7: 22240 | J7: 434-0492 | K7: 434-0491 | L7: 629-1424 | M7: 2 | N7: 2 | O7: 3 | P7: 3 | Q7: 3 | R7: 4 | S7: 2 | T7: 0 | U7: =SUM(M7:T7) -> 19 | V7: 42 | W7: 19 | X7: 48 | Y7: 19 | Z7: 54 | AA7: 28 | AB7: 76 | AC7: 36 | AD7: 74 | AE7: 36 | AF7: 93 | AG7: 49 | AH7: =V7+X7+Z7+AB7+AD7+AF7 -> 387 | AI7: =W7+Y7+AA7+AC7+AE7+AG7 -> 187 | AJ7: 13 | AK7: 5 | AL7: 0 | AM7: 0
A8: 남부 | B8: 미추홀구 | C8: 미추홀구 | D8: 공립 | E8: 인천남부초등학교 | F8: 28551 | G8: 미추홀구 인주대로366번길 22(주안동 1444) | H8: 10613 | I8: 22214 | J8: 629-1084 | K8: 865-5784 | L8: 865-5787 | M8: 2 | N8: 2 | O8: 2 | P8: 3 | Q8: 4 | R8: 2 | S8: 3 | T8: 0 | U8: =SUM(M8:T8) -> 18 | V8: 36 | W8: 14 | X8: 35 | Y8: 19 | Z8: 42 | AA8: 17 | AB8: 53 | AC8: 28 | AD8: 81 | AE8: 40 | AF8: 50 | AG8: 27 | AH8: =V8+X8+Z8+AB8+AD8+AF8 -> 297 | AI8: =W8+Y8+AA8+AC8+AE8+AG8 -> 145 | AJ8: 13 | AK8: 4 | AL8: 0 | AM8: 0
A9: 남부 | B9: 미추홀구 | C9: 미추홀구 | D9: 공립 | E9: 인천대화초등학교 | F9: 34394 | G9: 미추홀구 석정로301번길 13(도화동 105-11) | H9: 11867 | I9: 22116 | J9: 867-0046 | K9: 867-0047 | L9: 867-1356 | M9: 1 | N9: 2 | O9: 3 | P9: 3 | Q9: 3 | R9: 3 | S9: 3 | T9: 0 | U9: =SUM(M9:T9) -> 18 | V9: 23 | W9: 19 | X9: 38 | Y9: 23 | Z9: 51 | AA9: 26 | AB9: 51 | AC9: 28 | AD9: 51 | AE9: 25 | AF9: 74 | AG9: 36 | AH9: =V9+X9+Z9+AB9+AD9+AF9 -> 288 | AI9: =W9+Y9+AA9+AC9+AE9+AG9 -> 157 | AJ9: 15 | AK9: 6 | AL9: 0 | AM9: 0
A10: 남부 | B10: 미추홀구 | C10: 미추홀구 | D10: 공립 | E10: 인천도화초등학교 | F10: 17069 | G10: 미추홀구 경인로 242(도화동 541-5) | H10: 12366.3 | I10: 22165 | J10: 874-2585 | K10: 874-2582 | L10: 865-6134 | M10: 5 | N10: 5 | O10: 6 | P10: 6 | Q10: 6 | R10: 6 | S10: 4 | T10: 0 | U10: =SUM(M10:T10) -> 38 | V10: 115 | W10: 47 | X10: 112 | Y10: 47 | Z10: 136 | AA10: 68 | AB10: 137 | AC10: 70 | AD10: 144 | AE10: 83 | AF10: 140 | AG10: 67 | AH10: =V10+X10+Z10+AB10+AD10+AF10 -> 784 | AI10: =W10+Y10+AA10+AC10+AE10+AG10 -> 382 | AJ10: 22 | AK10: 7 | AL10: 0 | AM10: 0
A11: 남부 | B11: 미추홀구 | C11: 미추홀구 | D11: 공립 | E11: 인천문학초등학교 | F11: 6694 | G11: 미추홀구 매소홀로 553(문학동 343-2) | H11: 21350 | I11: 22233 | J11: 629-0102 | K11: 629-0101 | L11: 435-0367 | M11: 3 | N11: 3 | O11: 3 | P11: 4 | Q11: 4 | R11: 5 | S11: 3 | T11: 0 | U11: =SUM(M11:T11) -> 25 | V11: 51 | W11: 25 | X11: 70 | Y11: 33 | Z11: 70 | AA11: 36 | AB11: 82 | AC11: 34 | AD11: 97 | AE11: 49 | AF11: 110 | AG11: 58 | AH11: =V11+X11+Z11+AB11+AD11+AF11 -> 480 | AI11: =W11+Y11+AA11+AC11+AE11+AG11 -> 235 | AJ11: 17 | AK11: 4 | AL11: 0 | AM11: 0
A12: 남부 | B12: 미추홀구 | C12: 미추홀구 | D12: 공립 | E12: 인천백학초등학교 | F12: 32933 | G12: 미추홀구 매소홀로 446번길 25(학익동 674) | H12: 12590 | I12: 22226 | J12: 868-6778 | K12: 867-2883 | L12: 867-2884 | M12: 2 | N12: 3 | O12: 2 | P12: 2 | Q12: 2 | R12: 2 | S12: 3 | T12: 0 | U12: =SUM(M12:T12) -> 16 | V12: 38 | W12: 17 | X12: 61 | Y12: 34 | Z12: 41 | AA12: 20 | AB12: 45 | AC12: 17 | AD12: 47 | AE12: 21 | AF12: 53 | AG12: 27 | AH12: =V12+X12+Z12+AB12+AD12+AF12 -> 285 | AI12: =W12+Y12+AA12+AC12+AE12+AG12 -> 136 | AJ12: 16 | AK12: 8 | AL12: 0 | AM12: 0
A13: 남부 | B13: 미추홀구 | C13: 미추홀구 | D13: 공립 | E13: 인천서화초등학교 | F13: 24533 | G13: 미추홀구 송림로 250(도화동 1003) | H13: 19126 | I13: 22114 | J13: 868-9232 | K13: 868-9234 | L13: 868-9237 | M13: 8 | N13: 8 | O13: 9 | P13: 9 | Q13: 9 | R13: 9 | S13: 5 | T13: 0 | U13: =SUM(M13:T13) -> 57 | V13: 194 | W13: 104 | X13: 209 | Y13: 99 | Z13: 215 | AA13: 107 | AB13: 226 | AC13: 118 | AD13: 228 | AE13: 99 | AF13: 210 | AG13: 105 | AH13: =V13+X13+Z13+AB13+AD13+AF13 -> 1282 | AI13: =W13+Y13+AA13+AC13+AE13+AG13 -> 632 | AJ13: 26 | AK13: 9 | AL13: 0 | AM13: 0
A14: 남부 | B14: 미추홀구 | C14: 미추홀구 | D14: 공립 | E14: 인천석암초등학교 | F14: 25263 | G14: 미추홀구 주안동로 46(주안동 55-1) | H14: 14457 | I14: 22134 | J14: 424-0143 | K14: 424-0143 | L14: 432-7003 | M14: 6 | N14: 6 | O14: 7 | P14: 8 | Q14: 7 | R14: 7 | S14: 5 | T14: 1 | U14: =SUM(M14:T14) -> 47 | V14: 113 | W14: 57 | X14: 126 | Y14: 73 | Z14: 151 | AA14: 76 | AB14: 163 | AC14: 74 | AD14: 166 | AE14: 83 | AF14: 156 | AG14: 75 | AH14: =V14+X14+Z14+AB14+AD14+AF14 -> 875 | AI14: =W14+Y14+AA14+AC14+AE14+AG14 -> 438 | AJ14: 32 | AK14: 10 | AL14: 17 | AM14: 8
A15: 남부 | B15: 미추홀구 | C15: 미추홀구 | D15: 공립 | E15: 인천숭의초등학교 | F15: 13859 | G15: 미추홀구 장천로 99(숭의동 42-2) | H15: 15389 | I15: 22163 | J15: 887-9011 | K15: 887-9011 | L15: 887-9017 | M15: 7 | N15: 8 | O15: 8 | P15: 9 | Q15: 9 | R15: 8 | S15: 6 | T15: 0 | U15: =SUM(M15:T15) -> 55 | V15: 185 | W15: 92 | X15: 197 | Y15: 88 | Z15: 204 | AA15: 82 | AB15: 222 | AC15: 112 | AD15: 231 | AE15: 105 | AF15: 207 | AG15: 100 | AH15: =V15+X15+Z15+AB15+AD15+AF15 -> 1246 | AI15: =W15+Y15+AA15+AC15+AE15+AG15 -> 579 | AJ15: 33 | AK15: 7 | AL15: 0 | AM15: 0
